Workbook

Sheet Template
A1: =+'Annual Raw'!B2 -> 0 | B1: =+EOMONTH(C1,-12) -> 36981 | C1: =+EOMONTH(D1,-12) -> 37346 | D1: =+EOMONTH(E1,-12) -> 37711 | E1: =+EOMONTH(F1,-12) -> 38077 | F1: =+EOMONTH(G1,-12) -> 38442 | G1: =+EOMONTH(H1,-12) -> 38807 | H1: =+EOMONTH(I1,-12) -> 39172 | I1: =+EOMONTH(J1,-12) -> 39538 | ... N1: =+EOMONTH(O1,-12) -> 41364 | O1: 41699 | P1: 42064 | Q1: 42430 | R1: 42795 | S1: 43160 | T1: 43525 | U1: 43891 | V1: 44256 | W1: 44621 | X1: 44986 | Y1: 45352 | Z1: 45717 | AA1: 46082 | AB1: 46447 | AC1: 46813 | AD1: 47178 | AE1: 47543 | AG1: Quarterly | AH1: 42185 | AI1: =+EOMONTH(AH1,3) -> 42277 | AJ1: =+EOMONTH(AI1,3) -> 42369 | AK1: =+EOMONTH(AJ1,3) -> 42460 | AL1: =+EOMONTH(AK1,3) -> 42551 | AM1: =+EOMONTH(AL1,3) -> 42643 | AN1: =+EOMONTH(AM1,3) -> 42735 | AO1: =+EOMONTH(AN1,3) -> 42825 | AP1: =+EOMONTH(AO1,3) -> 42916 | ... CO1: =+EOMONTH(CN1,3) -> 47573
A2: Presentation Data (Start)
A4: Average eq | D4: =AVERAGE(C97:D97) -> 0 | E4: =AVERAGE(D97:E97) -> 0 | F4: =AVERAGE(E97:F97) -> 0 | G4: =AVERAGE(F97:G97) -> 0 | H4: =AVERAGE(G97:H97) -> 0 | I4: =AVERAGE(H97:I97) -> 0 | J4: =AVERAGE(I97:J97) -> 0 | K4: =AVERAGE(J97:K97) -> 0 | ... X4: =AVERAGE(W97:X97) -> 0 | Y4: =+AVERAGE(BN4:BQ4) -> 0 | Z4: =+AVERAGE(BR4:BU4) -> 0 | AA4: =+AVERAGE(BV4:BY4) -> 0 | AB4: =+AVERAGE(BZ4:CC4) -> #DIV/0! | AC4: =+AVERAGE(CD4:CG4) -> #DIV/0! | AD4: =+AVERAGE(CH4:CK4) -> #DIV/0! | AE4: =+AVERAGE(CL4:CO4) -> #DIV/0! | AH4: =+AVERAGE(AG97,AE97) -> #DIV/0! | AI4: =+AVERAGE(AI97,AG97) -> 0 | AJ4: =+AVERAGE(AI97,AG97) -> 0 | AK4: =+AVERAGE(AK97,AI97) -> 0 | AL4: =+AVERAGE(AK97,AI97) -> 0 | AM4: =+AVERAGE(AM97,AK97) -> 0 | AN4: =+AVERAGE(AM97,AK97) -> 0 | AO4: =+AVERAGE(AO97,AM97) -> 0 | AP4: =+AVERAGE(AO97,AM97) -> 0 | AQ4: =+AVERAGE(AQ97,AO97) -> 0 | AR4: =+AVERAGE(AQ97,AO97) -> 0 | AS4: =+AVERAGE(AS97,AQ97) -> 0 | AT4: =+AVERAGE(AS97,AQ97) -> 0 | AU4: =+AVERAGE(AU97,AS97) -> 0 | AV4: =+AVERAGE(AU97,AS97) -> 0 | AW4: =+AVERAGE(AW97,AU97) -> 0 | AX4: =+AVERAGE(AW97,AU97) -> 0 | AY4: =+AVERAGE(AY97,AW97) -> 0 | AZ4: =+AVERAGE(AY97,AW97) -> 0 | BA4: =+AVERAGE(BA97,AY97) -> 0 | BB4: =+AVERAGE(BA97,AY97) -> 0 | BC4: =+AVERAGE(BC97,BA97) -> 0 | BD4: =+AVERAGE(BC97,BA97) -> 0 | BE4: =+AVERAGE(BE97,BC97) -> 0 | BF4: =+AVERAGE(BE97,BC97) -> 0 | BG4: =+AVERAGE(BG97,BE97) -> 0 | BH4: =+AVERAGE(BG97,BE97) -> 0 | BI4: =+AVERAGE(BI97,BG97) -> 0 | BJ4: =+AVERAGE(BI97,BG97) -> 0 | BK4: =+AVERAGE(BK97,BI97) -> 0 | BL4: =+AVERAGE(BK97,BI97) -> 0 | BM4: =+AVERAGE(BM97,BK97) -> 0 | BN4: =+AVERAGE(BM97,BK97) -> 0 | BO4: =+AVERAGE(BO97,BM97) -> 0 | BP4: =+AVERAGE(BO97,BM97) -> 0 | BQ4: =+AVERAGE(BQ97,BO97) -> 0 | BR4: =+AVERAGE(BQ97,BO97) -> 0 | BS4: =+AVERAGE(BS97,BQ97) -> 0 | BT4: =+AVERAGE(BS97,BQ97) -> 0 | BU4: =+AVERAGE(BU97,BS97) -> 0 | BV4: =+AVERAGE(BU97,BS97) -> 0 | BW4: =+AVERAGE(BW97,BU97) -> 0 | BX4: =+AVERAGE(BW97,BU97) -> 0 | BY4: =+AVERAGE(BY97,BW97) -> 0 | BZ4: =+AVERAGE(BY97,BW97) -> 0 | CA4: =+AVERAGE(CA97,BY97) -> #DIV/0! | CB4: =+AVERAGE(CA97,BY97) -> #DIV/0! | CC4: =+AVERAGE(CC97,CA97) -> #DIV/0! | CD4: =+AVERAGE(CC97,CA97) -> #DIV/0! | CE4: =+AVERAGE(CE97,CC97) -> #DIV/0! | CF4: =+AVERAGE(CE97,CC97) -> #DIV/0! | CG4: =+AVERAGE(CG97,CE97) -> #DIV/0! | CH4: =+AVERAGE(CG97,CE97) -> #DIV/0! | CI4: =+AVERAGE(CI97,CG97) -> #DIV/0! | CJ4: =+AVERAGE(CI97,CG97) -> #DIV/0! | CK4: =+AVERAGE(CK97,CI97) -> #DIV/0! | CL4: =+AVERAGE(CK97,CI97) -> #DIV/0! | CM4: =+AVERAGE(CM97,CK97) -> #DIV/0! | CN4: =+AVERAGE(CM97,CK97) -> #DIV/0! | CO4: =+AVERAGE(CO97,CM97) -> #DIV/0!
A5: Average assets | D5: =AVERAGE(C106:D106) -> 0 | E5: =AVERAGE(D106:E106) -> 0 | F5: =AVERAGE(E106:F106) -> 0 | G5: =AVERAGE(F106:G106) -> 0 | H5: =AVERAGE(G106:H106) -> 0 | I5: =AVERAGE(H106:I106) -> 0 | J5: =AVERAGE(I106:J106) -> 0 | K5: =AVERAGE(J106:K106) -> 0 | ... X5: =AVERAGE(W106:X106) -> 0 | Y5: =+AVERAGE(BN5:BQ5) -> 0 | Z5: =+AVERAGE(BR5:BU5) -> 0 | AA5: =+AVERAGE(BV5:BY5) -> 0 | AB5: =+AVERAGE(BZ5:CC5) -> #DIV/0! | AC5: =+AVERAGE(CD5:CG5) -> #DIV/0! | AD5: =+AVERAGE(CH5:CK5) -> #DIV/0! | AE5: =+AVERAGE(CL5:CO5) -> #DIV/0! | AH5: =+AVERAGE(AG106,AE106) -> #DIV/0! | AI5: =+AVERAGE(AI106,AG106) -> 0 | AJ5: =+AVERAGE(AI106,AG106) -> 0 | AK5: =+AVERAGE(AK106,AI106) -> 0 | AL5: =+AVERAGE(AK106,AI106) -> 0 | AM5: =+AVERAGE(AM106,AK106) -> 0 | AN5: =+AVERAGE(AM106,AK106) -> 0 | AO5: =+AVERAGE(AO106,AM106) -> 0 | AP5: =+AVERAGE(AO106,AM106) -> 0 | AQ5: =+AVERAGE(AQ106,AO106) -> 0 | AR5: =+AVERAGE(AQ106,AO106) -> 0 | AS5: =+AVERAGE(AS106,AQ106) -> 0 | AT5: =+AVERAGE(AS106,AQ106) -> 0 | AU5: =+AVERAGE(AU106,AS106) -> 0 | AV5: =+AVERAGE(AU106,AS106) -> 0 | AW5: =+AVERAGE(AW106,AU106) -> 0 | AX5: =+AVERAGE(AW106,AU106) -> 0 | AY5: =+AVERAGE(AY106,AW106) -> 0 | AZ5: =+AVERAGE(AY106,AW106) -> 0 | BA5: =+AVERAGE(BA106,AY106) -> 0 | BB5: =+AVERAGE(BA106,AY106) -> 0 | BC5: =+AVERAGE(BC106,BA106) -> 0 | BD5: =+AVERAGE(BC106,BA106) -> 0 | BE5: =+AVERAGE(BE106,BC106) -> 0 | BF5: =+AVERAGE(BE106,BC106) -> 0 | BG5: =+AVERAGE(BG106,BE106) -> 0 | BH5: =+AVERAGE(BG106,BE106) -> 0 | BI5: =+AVERAGE(BI106,BG106) -> 0 | BJ5: =+AVERAGE(BI106,BG106) -> 0 | BK5: =+AVERAGE(BK106,BI106) -> 0 | BL5: =+AVERAGE(BK106,BI106) -> 0 | BM5: =+AVERAGE(BM106,BK106) -> 0 | BN5: =+AVERAGE(BM106,BK106) -> 0 | BO5: =+AVERAGE(BO106,BM106) -> 0 | BP5: =+AVERAGE(BO106,BM106) -> 0 | BQ5: =+AVERAGE(BQ106,BO106) -> 0 | BR5: =+AVERAGE(BQ106,BO106) -> 0 | BS5: =+AVERAGE(BS106,BQ106) -> 0 | BT5: =+AVERAGE(BS106,BQ106) -> 0 | BU5: =+AVERAGE(BU106,BS106) -> 0 | BV5: =+AVERAGE(BU106,BS106) -> 0 | BW5: =+AVERAGE(BW106,BU106) -> 0 | BX5: =+AVERAGE(BW106,BU106) -> 0 | BY5: =+AVERAGE(BY106,BW106) -> 0 | BZ5: =+AVERAGE(BY106,BW106) -> 0 | CA5: =+AVERAGE(CA106,BY106) -> #DIV/0! | CB5: =+AVERAGE(CA106,BY106) -> #DIV/0! | CC5: =+AVERAGE(CC106,CA106) -> #DIV/0! | CD5: =+AVERAGE(CC106,CA106) -> #DIV/0! | CE5: =+AVERAGE(CE106,CC106) -> #DIV/0! | CF5: =+AVERAGE(CE106,CC106) -> #DIV/0! | CG5: =+AVERAGE(CG106,CE106) -> #DIV/0! | CH5: =+AVERAGE(CG106,CE106) -> #DIV/0! | CI5: =+AVERAGE(CI106,CG106) -> #DIV/0! | CJ5: =+AVERAGE(CI106,CG106) -> #DIV/0! | CK5: =+AVERAGE(CK106,CI106) -> #DIV/0! | CL5: =+AVERAGE(CK106,CI106) -> #DIV/0! | CM5: =+AVERAGE(CM106,CK106) -> #DIV/0! | CN5: =+AVERAGE(CM106,CK106) -> #DIV/0! | CO5: =+AVERAGE(CO106,CM106) -> #DIV/0!
A7: Growth (%) | D7: =+D5/C5-1 -> #DIV/0! | E7: =+E5/D5-1 -> #DIV/0! | F7: =+F5/E5-1 -> #DIV/0! | G7: =+G5/F5-1 -> #DIV/0! | H7: =+H5/G5-1 -> #DIV/0! | I7: =+I5/H5-1 -> #DIV/0! | J7: =+J5/I5-1 -> #DIV/0! | K7: =+K5/J5-1 -> #DIV/0! | ... AE7: =+AE5/AD5-1 -> #DIV/0! | AL7: =AL5/AH5-1 -> #DIV/0! | AM7: =AM5/AI5-1 -> #DIV/0! | AN7: =AN5/AJ5-1 -> #DIV/0! | AO7: =AO5/AK5-1 -> #DIV/0! | AP7: =AP5/AL5-1 -> #DIV/0! | AQ7: =AQ5/AM5-1 -> #DIV/0! | AR7: =AR5/AN5-1 -> #DIV/0! | AS7: =AS5/AO5-1 -> #DIV/0! | ... CO7: =CO5/CK5-1 -> #DIV/0!
A9: Leverage | D9: =D105/D97 -> #DIV/0! | E9: =E105/E97 -> #DIV/0! | F9: =F105/F97 -> #DIV/0! | G9: =G105/G97 -> #DIV/0! | H9: =H105/H97 -> #DIV/0! | I9: =I105/I97 -> #DIV/0! | J9: =J105/J97 -> #DIV/0! | K9: =K105/K97 -> #DIV/0! | ... AE9: =AE105/AE97 -> #DIV/0! | AH9: =AH105/AH97 -> #DIV/0! | AI9: =AI105/AI97 -> #DIV/0! | AJ9: =AJ105/AJ97 -> #DIV/0! | AK9: =AK105/AK97 -> #DIV/0! | AL9: =AL105/AL97 -> #DIV/0! | AM9: =AM105/AM97 -> #DIV/0! | AN9: =AN105/AN97 -> #DIV/0! | AO9: =AO105/AO97 -> #DIV/0! | ... CO9: =CO105/CO97 -> #DIV/0!
A12: Interest Income | D12: =D27/C5 -> #DIV/0! | E12: =E27/D5 -> #DIV/0! | F12: =F27/E5 -> #DIV/0! | G12: =G27/F5 -> #DIV/0! | H12: =H27/G5 -> #DIV/0! | I12: =I27/H5 -> #DIV/0! | J12: =J27/I5 -> #DIV/0! | K12: =K27/J5 -> #DIV/0! | ... AE12: =AE27/AD5 -> #DIV/0! | AI12: =AI27/AH5 -> #DIV/0! | AJ12: =AJ27/AI5 -> #DIV/0! | AK12: =AK27/AJ5 -> #DIV/0! | AL12: =AL27/AK5 -> #DIV/0! | AM12: =AM27/AL5 -> #DIV/0! | AN12: =AN27/AM5 -> #DIV/0! | AO12: =AO27/AN5 -> #DIV/0! | AP12: =AP27/AO5 -> #DIV/0! | ... BY12: =BY27/BX5 -> #DIV/0! | BZ12: =+AVERAGE(BV12:BY12) -> #DIV/0! | CA12: =+AVERAGE(BW12:BZ12) -> #DIV/0! | CB12: =+AVERAGE(BX12:CA12) -> #DIV/0! | CC12: =+AVERAGE(BY12:CB12) -> #DIV/0! | CD12: =+AVERAGE(BZ12:CC12) -> #DIV/0! | CE12: =+AVERAGE(CA12:CD12) -> #DIV/0! | CF12: =+AVERAGE(CB12:CE12) -> #DIV/0! | CG12: =+AVERAGE(CC12:CF12) -> #DIV/0! | ... CO12: =+AVERAGE(CK12:CN12) -> #DIV/0!
A13: Interest Expenses | D13: =D28/C5 -> #DIV/0! | E13: =E28/D5 -> #DIV/0! | F13: =F28/E5 -> #DIV/0! | G13: =G28/F5 -> #DIV/0! | H13: =H28/G5 -> #DIV/0! | I13: =I28/H5 -> #DIV/0! | J13: =J28/I5 -> #DIV/0! | K13: =K28/J5 -> #DIV/0! | ... AE13: =AE28/AD5 -> #DIV/0! | AI13: =AI28/AH5 -> #DIV/0! | AJ13: =AJ28/AI5 -> #DIV/0! | AK13: =AK28/AJ5 -> #DIV/0! | AL13: =AL28/AK5 -> #DIV/0! | AM13: =AM28/AL5 -> #DIV/0! | AN13: =AN28/AM5 -> #DIV/0! | AO13: =AO28/AN5 -> #DIV/0! | AP13: =AP28/AO5 -> #DIV/0! | ... BY13: =BY28/BX5 -> #DIV/0! | BZ13: =+AVERAGE(BV13:BY13) -> #DIV/0! | CA13: =+AVERAGE(BW13:BZ13) -> #DIV/0! | CB13: =+AVERAGE(BX13:CA13) -> #DIV/0! | CC13: =+AVERAGE(BY13:CB13) -> #DIV/0! | CD13: =+AVERAGE(BZ13:CC13) -> #DIV/0! | CE13: =+AVERAGE(CA13:CD13) -> #DIV/0! | CF13: =+AVERAGE(CB13:CE13) -> #DIV/0! | CG13: =+AVERAGE(CC13:CF13) -> #DIV/0! | ... CO13: =+AVERAGE(CK13:CN13) -> #DIV/0!
A14: NII | D14: =D12-D13 -> #DIV/0! | E14: =E12-E13 -> #DIV/0! | F14: =F12-F13 -> #DIV/0! | G14: =G12-G13 -> #DIV/0! | H14: =H12-H13 -> #DIV/0! | I14: =I12-I13 -> #DIV/0! | J14: =J12-J13 -> #DIV/0! | K14: =K12-K13 -> #DIV/0! | ... AE14: =AE12-AE13 -> #DIV/0! | AI14: =AI12-AI13 -> #DIV/0! | AJ14: =AJ12-AJ13 -> #DIV/0! | AK14: =AK12-AK13 -> #DIV/0! | AL14: =AL12-AL13 -> #DIV/0! | AM14: =AM12-AM13 -> #DIV/0! | AN14: =AN12-AN13 -> #DIV/0! | AO14: =AO12-AO13 -> #DIV/0! | AP14: =AP12-AP13 -> #DIV/0! | ... CO14: =CO12-CO13 -> #DIV/0!
A15: Others income | D15: =D30/C5 -> #DIV/0! | E15: =E30/D5 -> #DIV/0! | F15: =F30/E5 -> #DIV/0! | G15: =G30/F5 -> #DIV/0! | H15: =H30/G5 -> #DIV/0! | I15: =I30/H5 -> #DIV/0! | J15: =J30/I5 -> #DIV/0! | K15: =K30/J5 -> #DIV/0! | ... AE15: =AE30/AD5 -> #DIV/0! | AI15: =AI30/AH5 -> #DIV/0! | AJ15: =AJ30/AI5 -> #DIV/0! | AK15: =AK30/AJ5 -> #DIV/0! | AL15: =AL30/AK5 -> #DIV/0! | AM15: =AM30/AL5 -> #DIV/0! | AN15: =AN30/AM5 -> #DIV/0! | AO15: =AO30/AN5 -> #DIV/0! | AP15: =AP30/AO5 -> #DIV/0! | ... BY15: =BY30/BX5 -> #DIV/0! | BZ15: =BY15 -> #DIV/0! | CA15: =BZ15 -> #DIV/0! | CB15: =CA15 -> #DIV/0! | CC15: =CB15 -> #DIV/0! | CD15: =CC15 -> #DIV/0! | CE15: =CD15 -> #DIV/0! | CF15: =CE15 -> #DIV/0! | CG15: =CF15 -> #DIV/0! | ... CO15: =CN15 -> #DIV/0!
A16: Other non-operating income
A17: Total income | D17: =D14+D15+D16 -> #DIV/0! | E17: =E14+E15+E16 -> #DIV/0! | F17: =F14+F15+F16 -> #DIV/0! | G17: =G14+G15+G16 -> #DIV/0! | H17: =H14+H15+H16 -> #DIV/0! | I17: =I14+I15+I16 -> #DIV/0! | J17: =J14+J15+J16 -> #DIV/0! | K17: =K14+K15+K16 -> #DIV/0! | ... AE17: =AE14+AE15+AE16 -> #DIV/0! | AI17: =AI14+AI15+AI16 -> #DIV/0! | AJ17: =AJ14+AJ15+AJ16 -> #DIV/0! | AK17: =AK14+AK15+AK16 -> #DIV/0! | AL17: =AL14+AL15+AL16 -> #DIV/0! | AM17: =AM14+AM15+AM16 -> #DIV/0! | AN17: =AN14+AN15+AN16 -> #DIV/0! | AO17: =AO14+AO15+AO16 -> #DIV/0! | AP17: =AP14+AP15+AP16 -> #DIV/0! | ... CO17: =CO14+CO15+CO16 -> #DIV/0!
A18: TC | D18: =D38/C5 -> #DIV/0! | E18: =E38/D5 -> #DIV/0! | F18: =F38/E5 -> #DIV/0! | G18: =G38/F5 -> #DIV/0! | H18: =H38/G5 -> #DIV/0! | I18: =I38/H5 -> #DIV/0! | J18: =J38/I5 -> #DIV/0! | K18: =K38/J5 -> #DIV/0! | ... AE18: =AE38/AD5 -> #DIV/0! | AI18: =AI38/AH5 -> #DIV/0! | AJ18: =AJ38/AI5 -> #DIV/0! | AK18: =AK38/AJ5 -> #DIV/0! | AL18: =AL38/AK5 -> #DIV/0! | AM18: =AM38/AL5 -> #DIV/0! | AN18: =AN38/AM5 -> #DIV/0! | AO18: =AO38/AN5 -> #DIV/0! | AP18: =AP38/AO5 -> #DIV/0! | ... BY18: =BY38/BX5 -> #DIV/0! | BZ18: =BY18 -> #DIV/0! | CA18: =BZ18 -> #DIV/0! | CB18: =CA18 -> #DIV/0! | CC18: =CB18 -> #DIV/0! | CD18: =CC18 -> #DIV/0! | CE18: =CD18 -> #DIV/0! | CF18: =CE18 -> #DIV/0! | CG18: =CF18 -> #DIV/0! | ... CO18: =CN18 -> #DIV/0!
A19: PPP | D19: =D17-D18 -> #DIV/0! | E19: =E17-E18 -> #DIV/0! | F19: =F17-F18 -> #DIV/0! | G19: =G17-G18 -> #DIV/0! | H19: =H17-H18 -> #DIV/0! | I19: =I17-I18 -> #DIV/0! | J19: =J17-J18 -> #DIV/0! | K19: =K17-K18 -> #DIV/0! | ... AE19: =AE17-AE18 -> #DIV/0! | AI19: =AI17-AI18 -> #DIV/0! | AJ19: =AJ17-AJ18 -> #DIV/0! | AK19: =AK17-AK18 -> #DIV/0! | AL19: =AL17-AL18 -> #DIV/0! | AM19: =AM17-AM18 -> #DIV/0! | AN19: =AN17-AN18 -> #DIV/0! | AO19: =AO17-AO18 -> #DIV/0! | AP19: =AP17-AP18 -> #DIV/0! | ... CO19: =CO17-CO18 -> #DIV/0!
A20: Provision | D20: =D41/C5 -> #DIV/0! | E20: =E41/D5 -> #DIV/0! | F20: =F41/E5 -> #DIV/0! | G20: =G41/F5 -> #DIV/0! | H20: =H41/G5 -> #DIV/0! | I20: =I41/H5 -> #DIV/0! | J20: =J41/I5 -> #DIV/0! | K20: =K41/J5 -> #DIV/0! | ... AE20: =AE41/AD5 -> #DIV/0! | AI20: =AI41/AH5 -> #DIV/0! | AJ20: =AJ41/AI5 -> #DIV/0! | AK20: =AK41/AJ5 -> #DIV/0! | AL20: =AL41/AK5 -> #DIV/0! | AM20: =AM41/AL5 -> #DIV/0! | AN20: =AN41/AM5 -> #DIV/0! | AO20: =AO41/AN5 -> #DIV/0! | AP20: =AP41/AO5 -> #DIV/0! | ... BY20: =BY41/BX5 -> #DIV/0! | BZ20: =BY20 -> #DIV/0! | CA20: =BZ20 -> #DIV/0! | CB20: =CA20 -> #DIV/0! | CC20: =CB20 -> #DIV/0! | CD20: =CC20 -> #DIV/0! | CE20: =CD20 -> #DIV/0! | CF20: =CE20 -> #DIV/0! | CG20: =CF20 -> #DIV/0! | ... CO20: =CN20 -> #DIV/0!
A21: PBT | D21: =D19-D20 -> #DIV/0! | E21: =E19-E20 -> #DIV/0! | F21: =F19-F20 -> #DIV/0! | G21: =G19-G20 -> #DIV/0! | H21: =H19-H20 -> #DIV/0! | I21: =I19-I20 -> #DIV/0! | J21: =J19-J20 -> #DIV/0! | K21: =K19-K20 -> #DIV/0! | ... AE21: =AE19-AE20 -> #DIV/0! | AI21: =AI19-AI20 -> #DIV/0! | AJ21: =AJ19-AJ20 -> #DIV/0! | AK21: =AK19-AK20 -> #DIV/0! | AL21: =AL19-AL20 -> #DIV/0! | AM21: =AM19-AM20 -> #DIV/0! | AN21: =AN19-AN20 -> #DIV/0! | AO21: =AO19-AO20 -> #DIV/0! | AP21: =AP19-AP20 -> #DIV/0! | ... CO21: =CO19-CO20 -> #DIV/0!
A22: Tax | D22: =D43/C5 -> #DIV/0! | E22: =E43/D5 -> #DIV/0! | F22: =F43/E5 -> #DIV/0! | G22: =G43/F5 -> #DIV/0! | H22: =H43/G5 -> #DIV/0! | I22: =I43/H5 -> #DIV/0! | J22: =J43/I5 -> #DIV/0! | K22: =K43/J5 -> #DIV/0! | ... AE22: =AE43/AD5 -> #DIV/0! | AI22: =AI43/AH5 -> #DIV/0! | AJ22: =AJ43/AI5 -> #DIV/0! | AK22: =AK43/AJ5 -> #DIV/0! | AL22: =AL43/AK5 -> #DIV/0! | AM22: =AM43/AL5 -> #DIV/0! | AN22: =AN43/AM5 -> #DIV/0! | AO22: =AO43/AN5 -> #DIV/0! | AP22: =AP43/AO5 -> #DIV/0! | ... CO22: =CO43/CN5 -> #DIV/0!
A23: PAT | D23: =D21-D22 -> #DIV/0! | E23: =E21-E22 -> #DIV/0! | F23: =F21-F22 -> #DIV/0! | G23: =G21-G22 -> #DIV/0! | H23: =H21-H22 -> #DIV/0! | I23: =I21-I22 -> #DIV/0! | J23: =J21-J22 -> #DIV/0! | K23: =K21-K22 -> #DIV/0! | ... AE23: =AE21-AE22 -> #DIV/0! | AI23: =AI21-AI22 -> #DIV/0! | AJ23: =AJ21-AJ22 -> #DIV/0! | AK23: =AK21-AK22 -> #DIV/0! | AL23: =AL21-AL22 -> #DIV/0! | AM23: =AM21-AM22 -> #DIV/0! | AN23: =AN21-AN22 -> #DIV/0! | AO23: =AO21-AO22 -> #DIV/0! | AP23: =AP21-AP22 -> #DIV/0! | ... CO23: =CO21-CO22 -> #DIV/0!
A25: Presentation Data (End)
A26: Profit & Loss- Annual (Start)
A27: Interest Income | B27: =+'Annual Raw'!C14 -> 0 | C27: =+'Annual Raw'!D14 -> 0 | D27: =+'Annual Raw'!E14 -> 0 | E27: =+'Annual Raw'!F14 -> 0 | F27: =+'Annual Raw'!G14 -> 0 | G27: =+'Annual Raw'!H14 -> 0 | H27: =+'Annual Raw'!I14 -> 0 | I27: =+'Annual Raw'!J14 -> 0 | ... Z27: =+'Annual Raw'!AA14 -> 0 | AA27: =SUM(BV27:BY27) -> 0 | AB27: =SUM(BZ27:CC27) -> #DIV/0! | AC27: =SUM(CD27:CG27) -> #DIV/0! | AD27: =SUM(CH27:CK27) -> #DIV/0! | AE27: =SUM(CL27:CO27) -> #DIV/0! | AH27: =+'QTR Raw'!D13 -> 0 | AI27: =+'QTR Raw'!E13 -> 0 | AJ27: =+'QTR Raw'!F13 -> 0 | AK27: =+'QTR Raw'!G13 -> 0 | AL27: =+'QTR Raw'!H13 -> 0 | AM27: =+'QTR Raw'!I13 -> 0 | AN27: =+'QTR Raw'!J13 -> 0 | AO27: =+'QTR Raw'!K13 -> 0 | ... BY27: =+'QTR Raw'!AU13 -> 0 | BZ27: =BZ12*BY5 -> #DIV/0! | CA27: =CA12*BZ5 -> #DIV/0! | CB27: =CB12*CA5 -> #DIV/0! | CC27: =CC12*CB5 -> #DIV/0! | CD27: =CD12*CC5 -> #DIV/0! | CE27: =CE12*CD5 -> #DIV/0! | CF27: =CF12*CE5 -> #DIV/0! | CG27: =CG12*CF5 -> #DIV/0! | ... CO27: =CO12*CN5 -> #DIV/0!
A28: Interest exp | B28: =+'Annual Raw'!C29 -> 0 | C28: =+'Annual Raw'!D29 -> 0 | D28: =+'Annual Raw'!E29 -> 0 | E28: =+'Annual Raw'!F29 -> 0 | F28: =+'Annual Raw'!G29 -> 0 | G28: =+'Annual Raw'!H29 -> 0 | H28: =+'Annual Raw'!I29 -> 0 | I28: =+'Annual Raw'!J29 -> 0 | ... Z28: =+'Annual Raw'!AA29 -> 0 | AA28: =SUM(BV28:BY28) -> 0 | AB28: =SUM(BZ28:CC28) -> #DIV/0! | AC28: =SUM(CD28:CG28) -> #DIV/0! | AD28: =SUM(CH28:CK28) -> #DIV/0! | AE28: =SUM(CL28:CO28) -> #DIV/0! | AH28: =+'QTR Raw'!D14+'QTR Raw'!D33 -> 0 | AI28: =+'QTR Raw'!E14+'QTR Raw'!E33 -> 0 | AJ28: =+'QTR Raw'!F14+'QTR Raw'!F33 -> 0 | AK28: =+'QTR Raw'!G14+'QTR Raw'!G33 -> 0 | AL28: =+'QTR Raw'!H14+'QTR Raw'!H33 -> 0 | AM28: =+'QTR Raw'!I14+'QTR Raw'!I33 -> 0 | AN28: =+'QTR Raw'!J14+'QTR Raw'!J33 -> 0 | AO28: =+'QTR Raw'!K14+'QTR Raw'!K33 -> 0 | ... BY28: =+'QTR Raw'!AU14+'QTR Raw'!AU33 -> 0 | BZ28: =BZ13*BY5 -> #DIV/0! | CA28: =CA13*BZ5 -> #DIV/0! | CB28: =CB13*CA5 -> #DIV/0! | CC28: =CC13*CB5 -> #DIV/0! | CD28: =CD13*CC5 -> #DIV/0! | CE28: =CE13*CD5 -> #DIV/0! | CF28: =CF13*CE5 -> #DIV/0! | CG28: =CG13*CF5 -> #DIV/0! | ... CO28: =CO13*CN5 -> #DIV/0!
A29: NII | B29: =B27-B28 -> 0 | C29: =C27-C28 -> 0 | D29: =D27-D28 -> 0 | E29: =E27-E28 -> 0 | F29: =F27-F28 -> 0 | G29: =G27-G28 -> 0 | H29: =H27-H28 -> 0 | I29: =I27-I28 -> 0 | ... AE29: =AE27-AE28 -> #DIV/0! | AH29: =AH27-AH28 -> 0 | AI29: =AI27-AI28 -> 0 | AJ29: =AJ27-AJ28 -> 0 | AK29: =AK27-AK28 -> 0 | AL29: =AL27-AL28 -> 0 | AM29: =AM27-AM28 -> 0 | AN29: =AN27-AN28 -> 0 | AO29: =AO27-AO28 -> 0 | ... CO29: =CO27-CO28 -> #DIV/0!
A30: Other Income | B30: =+'Annual Raw'!C27 -> 0 | C30: =+'Annual Raw'!D27 -> 0 | D30: =+'Annual Raw'!E27 -> 0 | E30: =+'Annual Raw'!F27 -> 0 | F30: =+'Annual Raw'!G27 -> 0 | G30: =+'Annual Raw'!H27 -> 0 | H30: =+'Annual Raw'!I27 -> 0 | I30: =+'Annual Raw'!J27 -> 0 | ... Z30: =+'Annual Raw'!AA27 -> 0 | AA30: =SUM(BV30:BY30) -> 0 | AB30: =SUM(BZ30:CC30) -> #DIV/0! | AC30: =SUM(CD30:CG30) -> #DIV/0! | AD30: =SUM(CH30:CK30) -> #DIV/0! | AE30: =SUM(CL30:CO30) -> #DIV/0! | AH30: =+'QTR Raw'!D32 -> 0 | AI30: =+'QTR Raw'!E32 -> 0 | AJ30: =+'QTR Raw'!F32 -> 0 | AK30: =+'QTR Raw'!G32 -> 0 | AL30: =+'QTR Raw'!H32 -> 0 | AM30: =+'QTR Raw'!I32 -> 0 | AN30: =+'QTR Raw'!J32 -> 0 | AO30: =+'QTR Raw'!K32 -> 0 | ... BY30: =+'QTR Raw'!AU32 -> 0 | BZ30: =BZ15*BY5 -> #DIV/0! | CA30: =CA15*BZ5 -> #DIV/0! | CB30: =CB15*CA5 -> #DIV/0! | CC30: =CC15*CB5 -> #DIV/0! | CD30: =CD15*CC5 -> #DIV/0! | CE30: =CE15*CD5 -> #DIV/0! | CF30: =CF15*CE5 -> #DIV/0! | CG30: =CG15*CF5 -> #DIV/0! | ... CO30: =CO15*CN5 -> #DIV/0!
A31: TI | B31: =B29+B30 -> 0 | C31: =C29+C30 -> 0 | D31: =D29+D30 -> 0 | E31: =E29+E30 -> 0 | F31: =F29+F30 -> 0 | G31: =G29+G30 -> 0 | H31: =H29+H30 -> 0 | I31: =I29+I30 -> 0 | ... AE31: =AE29+AE30 -> #DIV/0! | AH31: =AH29+AH30 -> 0 | AI31: =AI29+AI30 -> 0 | AJ31: =AJ29+AJ30 -> 0 | AK31: =AK29+AK30 -> 0 | AL31: =AL29+AL30 -> 0 | AM31: =AM29+AM30 -> 0 | AN31: =AN29+AN30 -> 0 | AO31: =AO29+AO30 -> 0 | ... CO31: =CO29+CO30 -> #DIV/0!
A32: YOY% | C32: =+IF(B31<0,1-C31/B31,C31/B31-1) -> #DIV/0! | D32: =+IF(C31<0,1-D31/C31,D31/C31-1) -> #DIV/0! | E32: =+IF(D31<0,1-E31/D31,E31/D31-1) -> #DIV/0! | F32: =+IF(E31<0,1-F31/E31,F31/E31-1) -> #DIV/0! | G32: =+IF(F31<0,1-G31/F31,G31/F31-1) -> #DIV/0! | H32: =+IF(G31<0,1-H31/G31,H31/G31-1) -> #DIV/0! | I32: =+IF(H31<0,1-I31/H31,I31/H31-1) -> #DIV/0! | J32: =+IF(I31<0,1-J31/I31,J31/I31-1) -> #DIV/0! | ... AE32: =+IF(AD31<0,1-AE31/AD31,AE31/AD31-1) -> #DIV/0! | AL32: =+IF(AH31<0,1-AL31/AH31,AL31/AH31-1) -> #DIV/0! | AM32: =+IF(AI31<0,1-AM31/AI31,AM31/AI31-1) -> #DIV/0! | AN32: =+IF(AJ31<0,1-AN31/AJ31,AN31/AJ31-1) -> #DIV/0! | AO32: =+IF(AK31<0,1-AO31/AK31,AO31/AK31-1) -> #DIV/0! | AP32: =+IF(AL31<0,1-AP31/AL31,AP31/AL31-1) -> #DIV/0! | AQ32: =+IF(AM31<0,1-AQ31/AM31,AQ31/AM31-1) -> #DIV/0! | AR32: =+IF(AN31<0,1-AR31/AN31,AR31/AN31-1) -> #DIV/0! | AS32: =+IF(AO31<0,1-AS31/AO31,AS31/AO31-1) -> #DIV/0! | ... CO32: =+IF(CK31<0,1-CO31/CK31,CO31/CK31-1) -> #DIV/0!
A33: Employee Cost | B33: =+'Annual Raw'!C18 -> 0 | C33: =+'Annual Raw'!D18 -> 0 | D33: =+'Annual Raw'!E18 -> 0 | E33: =+'Annual Raw'!F18 -> 0 | F33: =+'Annual Raw'!G18 -> 0 | G33: =+'Annual Raw'!H18 -> 0 | H33: =+'Annual Raw'!I18 -> 0 | I33: =+'Annual Raw'!J18 -> 0 | ... Z33: =+'Annual Raw'!AA18 -> 0 | AA33: =SUM(BV33:BY33) -> 0 | AB33: =SUM(BZ33:CC33) -> #DIV/0! | AC33: =SUM(CD33:CG33) -> #DIV/0! | AD33: =SUM(CH33:CK33) -> #DIV/0! | AE33: =SUM(CL33:CO33) -> #DIV/0! | AH33: =+'QTR Raw'!D20 -> 0 | AI33: =+'QTR Raw'!E20 -> 0 | AJ33: =+'QTR Raw'!F20 -> 0 | AK33: =+'QTR Raw'!G20 -> 0 | AL33: =+'QTR Raw'!H20 -> 0 | AM33: =+'QTR Raw'!I20 -> 0 | AN33: =+'QTR Raw'!J20 -> 0 | AO33: =+'QTR Raw'!K20 -> 0 | ... BY33: =+'QTR Raw'!AU20 -> 0 | BZ33: =BZ18*BY5 -> #DIV/0! | CA33: =CA18*BZ5 -> #DIV/0! | CB33: =CB18*CA5 -> #DIV/0! | CC33: =CC18*CB5 -> #DIV/0! | CD33: =CD18*CC5 -> #DIV/0! | CE33: =CE18*CD5 -> #DIV/0! | CF33: =CF18*CE5 -> #DIV/0! | CG33: =CG18*CF5 -> #DIV/0! | ... CO33: =CO18*CN5 -> #DIV/0!
A34: Operating & Establishment Expenses | B34: =+'Annual Raw'!C19+'Annual Raw'!C20+'Annual Raw'!C21+'Annual Raw'!C17+'Annual Raw'!C16+'Annual Raw'!C15-'Annual Raw'!C24 -> 0 | C34: =+'Annual Raw'!D19+'Annual Raw'!D20+'Annual Raw'!D21+'Annual Raw'!D17+'Annual Raw'!D16+'Annual Raw'!D15-'Annual Raw'!D24 -> 0 | D34: =+'Annual Raw'!E19+'Annual Raw'!E20+'Annual Raw'!E21+'Annual Raw'!E17+'Annual Raw'!E16+'Annual Raw'!E15-'Annual Raw'!E24 -> 0 | E34: =+'Annual Raw'!F19+'Annual Raw'!F20+'Annual Raw'!F21+'Annual Raw'!F17+'Annual Raw'!F16+'Annual Raw'!F15-'Annual Raw'!F24 -> 0 | F34: =+'Annual Raw'!G19+'Annual Raw'!G20+'Annual Raw'!G21+'Annual Raw'!G17+'Annual Raw'!G16+'Annual Raw'!G15-'Annual Raw'!G24 -> 0 | G34: =+'Annual Raw'!H19+'Annual Raw'!H20+'Annual Raw'!H21+'Annual Raw'!H17+'Annual Raw'!H16+'Annual Raw'!H15-'Annual Raw'!H24 -> 0 | H34: =+'Annual Raw'!I19+'Annual Raw'!I20+'Annual Raw'!I21+'Annual Raw'!I17+'Annual Raw'!I16+'Annual Raw'!I15-'Annual Raw'!I24 -> 0 | I34: =+'Annual Raw'!J19+'Annual Raw'!J20+'Annual Raw'!J21+'Annual Raw'!J17+'Annual Raw'!J16+'Annual Raw'!J15-'Annual Raw'!J24 -> 0 | ... Z34: =+'Annual Raw'!AA19+'Annual Raw'!AA20+'Annual Raw'!AA21+'Annual Raw'!AA17+'Annual Raw'!AA16+'Annual Raw'!AA15-'Annual Raw'!AA24 -> 0 | AA34: =SUM(BV34:BY34) -> 0 | AB34: =SUM(BZ34:CC34) -> 0 | AC34: =SUM(CD34:CG34) -> 0 | AD34: =SUM(CH34:CK34) -> 0 | AE34: =SUM(CL34:CO34) -> 0 | AH34: =+'QTR Raw'!D15+'QTR Raw'!D21+'QTR Raw'!D17+'QTR Raw'!D18+'QTR Raw'!D19+'QTR Raw'!D16+'QTR Raw'!D25 -> 0 | AI34: =+'QTR Raw'!E15+'QTR Raw'!E21+'QTR Raw'!E17+'QTR Raw'!E18+'QTR Raw'!E19+'QTR Raw'!E16+'QTR Raw'!E25 -> 0 | AJ34: =+'QTR Raw'!F15+'QTR Raw'!F21+'QTR Raw'!F17+'QTR Raw'!F18+'QTR Raw'!F19+'QTR Raw'!F16+'QTR Raw'!F25 -> 0 | AK34: =+'QTR Raw'!G15+'QTR Raw'!G21+'QTR Raw'!G17+'QTR Raw'!G18+'QTR Raw'!G19+'QTR Raw'!G16+'QTR Raw'!G25 -> 0 | AL34: =+'QTR Raw'!H15+'QTR Raw'!H21+'QTR Raw'!H17+'QTR Raw'!H18+'QTR Raw'!H19+'QTR Raw'!H16+'QTR Raw'!H25 -> 0 | AM34: =+'QTR Raw'!I15+'QTR Raw'!I21+'QTR Raw'!I17+'QTR Raw'!I18+'QTR Raw'!I19+'QTR Raw'!I16+'QTR Raw'!I25 -> 0 | AN34: =+'QTR Raw'!J15+'QTR Raw'!J21+'QTR Raw'!J17+'QTR Raw'!J18+'QTR Raw'!J19+'QTR Raw'!J16+'QTR Raw'!J25 -> 0 | AO34: =+'QTR Raw'!K15+'QTR Raw'!K21+'QTR Raw'!K17+'QTR Raw'!K18+'QTR Raw'!K19+'QTR Raw'!K16+'QTR Raw'!K25 -> 0 | ... BY34: =+'QTR Raw'!AU15+'QTR Raw'!AU21+'QTR Raw'!AU17+'QTR Raw'!AU18+'QTR Raw'!AU19+'QTR Raw'!AU16+'QTR Raw'!AU25 -> 0
A35: Depreciation | B35: =+'Annual Raw'!C31 -> 0 | C35: =+'Annual Raw'!D31 -> 0 | D35: =+'Annual Raw'!E31 -> 0 | E35: =+'Annual Raw'!F31 -> 0 | F35: =+'Annual Raw'!G31 -> 0 | G35: =+'Annual Raw'!H31 -> 0 | H35: =+'Annual Raw'!I31 -> 0 | I35: =+'Annual Raw'!J31 -> 0 | ... Z35: =+'Annual Raw'!AA31 -> 0 | AA35: =SUM(BV35:BY35) -> 0 | AB35: =SUM(BZ35:CC35) -> 0 | AC35: =SUM(CD35:CG35) -> 0 | AD35: =SUM(CH35:CK35) -> 0 | AE35: =SUM(CL35:CO35) -> 0 | AH35: =+'QTR Raw'!D37 -> 0 | AI35: =+'QTR Raw'!E37 -> 0 | AJ35: =+'QTR Raw'!F37 -> 0 | AK35: =+'QTR Raw'!G37 -> 0 | AL35: =+'QTR Raw'!H37 -> 0 | AM35: =+'QTR Raw'!I37 -> 0 | AN35: =+'QTR Raw'!J37 -> 0 | AO35: =+'QTR Raw'!K37 -> 0 | ... BY35: =+'QTR Raw'!AU37 -> 0
A36: Advertisement & Sales Promotion | B36: =+'Annual Raw'!C22 -> 0 | C36: =+'Annual Raw'!D22 -> 0 | D36: =+'Annual Raw'!E22 -> 0 | E36: =+'Annual Raw'!F22 -> 0 | F36: =+'Annual Raw'!G22 -> 0 | G36: =+'Annual Raw'!H22 -> 0 | H36: =+'Annual Raw'!I22 -> 0 | I36: =+'Annual Raw'!J22 -> 0 | ... Z36: =+'Annual Raw'!AA22 -> 0 | AA36: =SUM(BV36:BY36) -> 0 | AB36: =SUM(BZ36:CC36) -> 0 | AC36: =SUM(CD36:CG36) -> 0 | AD36: =SUM(CH36:CK36) -> 0 | AE36: =SUM(CL36:CO36) -> 0 | AH36: =+'QTR Raw'!D22 -> 0 | AI36: =+'QTR Raw'!E22 -> 0 | AJ36: =+'QTR Raw'!F22 -> 0 | AK36: =+'QTR Raw'!G22 -> 0 | AL36: =+'QTR Raw'!H22 -> 0 | AM36: =+'QTR Raw'!I22 -> 0 | AN36: =+'QTR Raw'!J22 -> 0 | AO36: =+'QTR Raw'!K22 -> 0 | ... BY36: =+'QTR Raw'!AU22 -> 0
A37: Other Expenses | AH37: =+'QTR Raw'!D23+'QTR Raw'!D24+'QTR Raw'!D26 -> 0 | AI37: =+'QTR Raw'!E23+'QTR Raw'!E24+'QTR Raw'!E26 -> 0 | AJ37: =+'QTR Raw'!F23+'QTR Raw'!F24+'QTR Raw'!F26 -> 0 | AK37: =+'QTR Raw'!G23+'QTR Raw'!G24+'QTR Raw'!G26 -> 0 | AL37: =+'QTR Raw'!H23+'QTR Raw'!H24+'QTR Raw'!H26 -> 0 | AM37: =+'QTR Raw'!I23+'QTR Raw'!I24+'QTR Raw'!I26 -> 0 | AN37: =+'QTR Raw'!J23+'QTR Raw'!J24+'QTR Raw'!J26 -> 0 | AO37: =+'QTR Raw'!K23+'QTR Raw'!K24+'QTR Raw'!K26 -> 0 | ... BY37: =+'QTR Raw'!AU23+'QTR Raw'!AU24+'QTR Raw'!AU26 -> 0
A38: TC | B38: =SUM(B33:B37) -> 0 | C38: =SUM(C33:C37) -> 0 | D38: =SUM(D33:D37) -> 0 | E38: =SUM(E33:E37) -> 0 | F38: =SUM(F33:F37) -> 0 | G38: =SUM(G33:G37) -> 0 | H38: =SUM(H33:H37) -> 0 | I38: =SUM(I33:I37) -> 0 | ... AE38: =SUM(AE33:AE37) -> #DIV/0! | AH38: =SUM(AH33:AH37) -> 0 | AI38: =SUM(AI33:AI37) -> 0 | AJ38: =SUM(AJ33:AJ37) -> 0 | AK38: =SUM(AK33:AK37) -> 0 | AL38: =SUM(AL33:AL37) -> 0 | AM38: =SUM(AM33:AM37) -> 0 | AN38: =SUM(AN33:AN37) -> 0 | AO38: =SUM(AO33:AO37) -> 0 | ... CO38: =SUM(CO33:CO37) -> #DIV/0!
A39: PPP | B39: =+B31-B38 -> 0 | C39: =+C31-C38 -> 0 | D39: =+D31-D38 -> 0 | E39: =+E31-E38 -> 0 | F39: =+F31-F38 -> 0 | G39: =+G31-G38 -> 0 | H39: =+H31-H38 -> 0 | I39: =+I31-I38 -> 0 | ... AE39: =+AE31-AE38 -> #DIV/0! | AH39: =+AH31-AH38 -> 0 | AI39: =+AI31-AI38 -> 0 | AJ39: =+AJ31-AJ38 -> 0 | AK39: =+AK31-AK38 -> 0 | AL39: =+AL31-AL38 -> 0 | AM39: =+AM31-AM38 -> 0 | AN39: =+AN31-AN38 -> 0 | AO39: =+AO31-AO38 -> 0 | ... CO39: =+CO31-CO38 -> #DIV/0!
A40: YOY% | C40: =+IF(B39<0,1-C39/B39,C39/B39-1) -> #DIV/0! | D40: =+IF(C39<0,1-D39/C39,D39/C39-1) -> #DIV/0! | E40: =+IF(D39<0,1-E39/D39,E39/D39-1) -> #DIV/0! | F40: =+IF(E39<0,1-F39/E39,F39/E39-1) -> #DIV/0! | G40: =+IF(F39<0,1-G39/F39,G39/F39-1) -> #DIV/0! | H40: =+IF(G39<0,1-H39/G39,H39/G39-1) -> #DIV/0! | I40: =+IF(H39<0,1-I39/H39,I39/H39-1) -> #DIV/0! | J40: =+IF(I39<0,1-J39/I39,J39/I39-1) -> #DIV/0! | ... AE40: =+IF(AD39<0,1-AE39/AD39,AE39/AD39-1) -> #DIV/0! | AL40: =+IF(AH39<0,1-AL39/AH39,AL39/AH39-1) -> #DIV/0! | AM40: =+IF(AI39<0,1-AM39/AI39,AM39/AI39-1) -> #DIV/0! | AN40: =+IF(AJ39<0,1-AN39/AJ39,AN39/AJ39-1) -> #DIV/0! | AO40: =+IF(AK39<0,1-AO39/AK39,AO39/AK39-1) -> #DIV/0! | AP40: =+IF(AL39<0,1-AP39/AL39,AP39/AL39-1) -> #DIV/0! | AQ40: =+IF(AM39<0,1-AQ39/AM39,AQ39/AM39-1) -> #DIV/0! | AR40: =+IF(AN39<0,1-AR39/AN39,AR39/AN39-1) -> #DIV/0! | AS40: =+IF(AO39<0,1-AS39/AO39,AS39/AO39-1) -> #DIV/0! | ... CO40: =+IF(CK39<0,1-CO39/CK39,CO39/CK39-1) -> #DIV/0!
A41: Provisions and Contingencies | B41: =+'Annual Raw'!C23 -> 0 | C41: =+'Annual Raw'!D23 -> 0 | D41: =+'Annual Raw'!E23 -> 0 | E41: =+'Annual Raw'!F23 -> 0 | F41: =+'Annual Raw'!G23 -> 0 | G41: =+'Annual Raw'!H23 -> 0 | H41: =+'Annual Raw'!I23 -> 0 | I41: =+'Annual Raw'!J23 -> 0 | ... Z41: =+'Annual Raw'!AA23 -> 0 | AA41: =SUM(BV41:BY41) -> 0 | AB41: =SUM(BZ41:CC41) -> #DIV/0! | AC41: =SUM(CD41:CG41) -> #DIV/0! | AD41: =SUM(CH41:CK41) -> #DIV/0! | AE41: =SUM(CL41:CO41) -> #DIV/0! | AH41: =+'QTR Raw'!D36+'QTR Raw'!D27 -> 0 | AI41: =+'QTR Raw'!E36+'QTR Raw'!E27 -> 0 | AJ41: =+'QTR Raw'!F36+'QTR Raw'!F27 -> 0 | AK41: =+'QTR Raw'!G36+'QTR Raw'!G27 -> 0 | AL41: =+'QTR Raw'!H36+'QTR Raw'!H27 -> 0 | AM41: =+'QTR Raw'!I36+'QTR Raw'!I27 -> 0 | AN41: =+'QTR Raw'!J36+'QTR Raw'!J27 -> 0 | AO41: =+'QTR Raw'!K36+'QTR Raw'!K27 -> 0 | ... BY41: =+'QTR Raw'!AU36+'QTR Raw'!AU27 -> 0 | BZ41: =BZ20*BY5 -> #DIV/0! | CA41: =CA20*BZ5 -> #DIV/0! | CB41: =CB20*CA5 -> #DIV/0! | CC41: =CC20*CB5 -> #DIV/0! | CD41: =CD20*CC5 -> #DIV/0! | CE41: =CE20*CD5 -> #DIV/0! | CF41: =CF20*CE5 -> #DIV/0! | CG41: =CG20*CF5 -> #DIV/0! | ... CO41: =CO20*CN5 -> #DIV/0!
A42: PBT | B42: =B39-B41 -> 0 | C42: =C39-C41 -> 0 | D42: =D39-D41 -> 0 | E42: =E39-E41 -> 0 | F42: =F39-F41 -> 0 | G42: =G39-G41 -> 0 | H42: =H39-H41 -> 0 | I42: =I39-I41 -> 0 | ... AE42: =AE39-AE41 -> #DIV/0! | AH42: =AH39-AH41 -> 0 | AI42: =AI39-AI41 -> 0 | AJ42: =AJ39-AJ41 -> 0 | AK42: =AK39-AK41 -> 0 | AL42: =AL39-AL41 -> 0 | AM42: =AM39-AM41 -> 0 | AN42: =AN39-AN41 -> 0 | AO42: =AO39-AO41 -> 0 | ... CO42: =CO39-CO41 -> #DIV/0!
A43: Tax | B43: =+'Annual Raw'!C36 -> 0 | C43: =+'Annual Raw'!D36 -> 0 | D43: =+'Annual Raw'!E36 -> 0 | E43: =+'Annual Raw'!F36 -> 0 | F43: =+'Annual Raw'!G36 -> 0 | G43: =+'Annual Raw'!H36 -> 0 | H43: =+'Annual Raw'!I36 -> 0 | I43: =+'Annual Raw'!J36 -> 0 | ... Z43: =+'Annual Raw'!AA36 -> 0 | AA43: =SUM(BV43:BY43) -> 0 | AB43: =SUM(BZ43:CC43) -> #DIV/0! | AC43: =SUM(CD43:CG43) -> #DIV/0! | AD43: =SUM(CH43:CK43) -> #DIV/0! | AE43: =SUM(CL43:CO43) -> #DIV/0! | AH43: =+'QTR Raw'!D38 -> 0 | AI43: =+'QTR Raw'!E38 -> 0 | AJ43: =+'QTR Raw'!F38 -> 0 | AK43: =+'QTR Raw'!G38 -> 0 | AL43: =+'QTR Raw'!H38 -> 0 | AM43: =+'QTR Raw'!I38 -> 0 | AN43: =+'QTR Raw'!J38 -> 0 | AO43: =+'QTR Raw'!K38 -> 0 | ... BY43: =+'QTR Raw'!AU38 -> 0 | BZ43: =BZ42*0.26 -> #DIV/0! | CA43: =CA42*0.26 -> #DIV/0! | CB43: =CB42*0.26 -> #DIV/0! | CC43: =CC42*0.26 -> #DIV/0! | CD43: =CD42*0.26 -> #DIV/0! | CE43: =CE42*0.26 -> #DIV/0! | CF43: =CF42*0.26 -> #DIV/0! | CG43: =CG42*0.26 -> #DIV/0! | ... CO43: =CO42*0.26 -> #DIV/0!
A44: PAT | B44: =B42-B43 -> 0 | C44: =C42-C43 -> 0 | D44: =D42-D43 -> 0 | E44: =E42-E43 -> 0 | F44: =F42-F43 -> 0 | G44: =G42-G43 -> 0 | H44: =H42-H43 -> 0 | I44: =I42-I43 -> 0 | ... AE44: =AE42-AE43 -> #DIV/0! | AH44: =AH42-AH43 -> 0 | AI44: =AI42-AI43 -> 0 | AJ44: =AJ42-AJ43 -> 0 | AK44: =AK42-AK43 -> 0 | AL44: =AL42-AL43 -> 0 | AM44: =AM42-AM43 -> 0 | AN44: =AN42-AN43 -> 0 | AO44: =AO42-AO43 -> 0 | ... CO44: =CO42-CO43 -> #DIV/0!
A45: Minority Interest | B45: =+'Annual Raw'!C42 -> 0 | C45: =+'Annual Raw'!D42 -> 0 | D45: =+'Annual Raw'!E42 -> 0 | E45: =+'Annual Raw'!F42 -> 0 | F45: =+'Annual Raw'!G42 -> 0 | G45: =+'Annual Raw'!H42 -> 0 | H45: =+'Annual Raw'!I42 -> 0 | I45: =+'Annual Raw'!J42 -> 0 | ... Z45: =+'Annual Raw'!AA42 -> 0 | AA45: =SUM(BV45:BY45) -> 0 | AB45: =SUM(BZ45:CC45) -> 0 | AC45: =SUM(CD45:CG45) -> 0 | AD45: =SUM(CH45:CK45) -> 0 | AE45: =SUM(CL45:CO45) -> 0 | AH45: =+'QTR Raw'!D39 -> 0 | AI45: =+'QTR Raw'!E39 -> 0 | AJ45: =+'QTR Raw'!F39 -> 0 | AK45: =+'QTR Raw'!G39 -> 0 | AL45: =+'QTR Raw'!H39 -> 0 | AM45: =+'QTR Raw'!I39 -> 0 | AN45: =+'QTR Raw'!J39 -> 0 | AO45: =+'QTR Raw'!K39 -> 0 | ... BY45: =+'QTR Raw'!AU39 -> 0 | BZ45: =+BY45 -> 0 | CA45: =+BZ45 -> 0 | CB45: =+CA45 -> 0 | CC45: =+CB45 -> 0 | CD45: =+CC45 -> 0 | CE45: =+CD45 -> 0 | CF45: =+CE45 -> 0 | CG45: =+CF45 -> 0 | ... CO45: =+CN45 -> 0
A46: Share of Associates | B46: =+'Annual Raw'!C43 -> 0 | C46: =+'Annual Raw'!D43 -> 0 | D46: =+'Annual Raw'!E43 -> 0 | E46: =+'Annual Raw'!F43 -> 0 | F46: =+'Annual Raw'!G43 -> 0 | G46: =+'Annual Raw'!H43 -> 0 | H46: =+'Annual Raw'!I43 -> 0 | I46: =+'Annual Raw'!J43 -> 0 | ... Z46: =+'Annual Raw'!AA43 -> 0 | AA46: =SUM(BV46:BY46) -> 0 | AB46: =SUM(BZ46:CC46) -> 0 | AC46: =SUM(CD46:CG46) -> 0 | AD46: =SUM(CH46:CK46) -> 0 | AE46: =SUM(CL46:CO46) -> 0 | AH46: =+'QTR Raw'!D40 -> 0 | AI46: =+'QTR Raw'!E40 -> 0 | AJ46: =+'QTR Raw'!F40 -> 0 | AK46: =+'QTR Raw'!G40 -> 0 | AL46: =+'QTR Raw'!H40 -> 0 | AM46: =+'QTR Raw'!I40 -> 0 | AN46: =+'QTR Raw'!J40 -> 0 | AO46: =+'QTR Raw'!K40 -> 0 | ... BY46: =+'QTR Raw'!AU40 -> 0 | BZ46: =+BY46 -> 0 | CA46: =+BZ46 -> 0 | CB46: =+CA46 -> 0 | CC46: =+CB46 -> 0 | CD46: =+CC46 -> 0 | CE46: =+CD46 -> 0 | CF46: =+CE46 -> 0 | CG46: =+CF46 -> 0 | ... CO46: =+CN46 -> 0
...

Sheet Annual Raw
B1: X | C1: 200103 | D1: 200203 | E1: 200303 | F1: 200403 | G1: 200503 | H1: 200603 | I1: 200703 | J1: 200803 | K1: 200903 | L1: 201003 | M1: 201103 | N1: 201203 | O1: 201303 | P1: 201403 | Q1: 201503 | R1: 201603 | S1: 201703 | T1: 201803 | U1: 201903 | V1: 202003 | W1: 202103 | X1: 202203 | Y1: 202303 | Z1: 202403 | AA1: 202503 | AB1: 202603 | AC1: 202703 | AD1: 202803 | AE1: 202903 | AF1: 203003
B2: {=_xll.EQNXTDZ($A$1,$B3,C$2)} -> 0
A3: Company Name | B3: CD_COMPNAME
A4: Field Description | B4: Field Name
A5: No of Months | B5: BPL_NO_MONTHS | C5: {=_xll.EQNXTDZ($A$1,$B5,C$1,$B$1)} -> 0 | D5: {=_xll.EQNXTDZ($A$1,$B5,D$1,$B$1)} -> 0 | E5: {=_xll.EQNXTDZ($A$1,$B5,E$1,$B$1)} -> 0 | F5: {=_xll.EQNXTDZ($A$1,$B5,F$1,$B$1)} -> 0 | G5: {=_xll.EQNXTDZ($A$1,$B5,G$1,$B$1)} -> 0 | H5: {=_xll.EQNXTDZ($A$1,$B5,H$1,$B$1)} -> 0 | I5: {=_xll.EQNXTDZ($A$1,$B5,I$1,$B$1)} -> 0 | J5: {=_xll.EQNXTDZ($A$1,$B5,J$1,$B$1)} -> 0 | ... AF5: {=_xll.EQNXTDZ($A$1,$B5,AF$1,$B$1)} -> 0
A6: Year end date | B6: BPL_YEAR_ENDDATE | C6: {=_xll.EQNXTDZ($A$1,$B6,C$1,$B$1)} -> 0 | D6: {=_xll.EQNXTDZ($A$1,$B6,D$1,$B$1)} -> 0 | E6: {=_xll.EQNXTDZ($A$1,$B6,E$1,$B$1)} -> 0 | F6: {=_xll.EQNXTDZ($A$1,$B6,F$1,$B$1)} -> 0 | G6: {=_xll.EQNXTDZ($A$1,$B6,G$1,$B$1)} -> 0 | H6: {=_xll.EQNXTDZ($A$1,$B6,H$1,$B$1)} -> 0 | I6: {=_xll.EQNXTDZ($A$1,$B6,I$1,$B$1)} -> 0 | J6: {=_xll.EQNXTDZ($A$1,$B6,J$1,$B$1)} -> 0 | ... AF6: {=_xll.EQNXTDZ($A$1,$B6,AF$1,$B$1)} -> 0
A8: Field Description | B8: Field Name
A9: Year End | B9: PL_YEAR_END | C9: {=_xll.EQNXTDZ($A$1,$B9,C$1,$B$1)} -> 0 | D9: {=_xll.EQNXTDZ($A$1,$B9,D$1,$B$1)} -> 0 | E9: {=_xll.EQNXTDZ($A$1,$B9,E$1,$B$1)} -> 0 | F9: {=_xll.EQNXTDZ($A$1,$B9,F$1,$B$1)} -> 0 | G9: {=_xll.EQNXTDZ($A$1,$B9,G$1,$B$1)} -> 0 | H9: {=_xll.EQNXTDZ($A$1,$B9,H$1,$B$1)} -> 0 | I9: {=_xll.EQNXTDZ($A$1,$B9,I$1,$B$1)} -> 0 | J9: {=_xll.EQNXTDZ($A$1,$B9,J$1,$B$1)} -> 0 | ... AF9: {=_xll.EQNXTDZ($A$1,$B9,AF$1,$B$1)} -> 0
A10: Year | B10: PL_YEAR | C10: {=_xll.EQNXTDZ($A$1,$B10,C$1,$B$1)} -> 0 | D10: {=_xll.EQNXTDZ($A$1,$B10,D$1,$B$1)} -> 0 | E10: {=_xll.EQNXTDZ($A$1,$B10,E$1,$B$1)} -> 0 | F10: {=_xll.EQNXTDZ($A$1,$B10,F$1,$B$1)} -> 0 | G10: {=_xll.EQNXTDZ($A$1,$B10,G$1,$B$1)} -> 0 | H10: {=_xll.EQNXTDZ($A$1,$B10,H$1,$B$1)} -> 0 | I10: {=_xll.EQNXTDZ($A$1,$B10,I$1,$B$1)} -> 0 | J10: {=_xll.EQNXTDZ($A$1,$B10,J$1,$B$1)} -> 0 | ... AF10: {=_xll.EQNXTDZ($A$1,$B10,AF$1,$B$1)} -> 0
A11: Year end date | B11: PL_YEAR_ENDDATE | C11: {=_xll.EQNXTDZ($A$1,$B11,C$1,$B$1)} -> 0 | D11: {=_xll.EQNXTDZ($A$1,$B11,D$1,$B$1)} -> 0 | E11: {=_xll.EQNXTDZ($A$1,$B11,E$1,$B$1)} -> 0 | F11: {=_xll.EQNXTDZ($A$1,$B11,F$1,$B$1)} -> 0 | G11: {=_xll.EQNXTDZ($A$1,$B11,G$1,$B$1)} -> 0 | H11: {=_xll.EQNXTDZ($A$1,$B11,H$1,$B$1)} -> 0 | I11: {=_xll.EQNXTDZ($A$1,$B11,I$1,$B$1)} -> 0 | J11: {=_xll.EQNXTDZ($A$1,$B11,J$1,$B$1)} -> 0 | ... AF11: {=_xll.EQNXTDZ($A$1,$B11,AF$1,$B$1)} -> 0
A12: No of Months | B12: PL_NO_MONTHS | C12: {=_xll.EQNXTDZ($A$1,$B12,C$1,$B$1)} -> 0 | D12: {=_xll.EQNXTDZ($A$1,$B12,D$1,$B$1)} -> 0 | E12: {=_xll.EQNXTDZ($A$1,$B12,E$1,$B$1)} -> 0 | F12: {=_xll.EQNXTDZ($A$1,$B12,F$1,$B$1)} -> 0 | G12: {=_xll.EQNXTDZ($A$1,$B12,G$1,$B$1)} -> 0 | H12: {=_xll.EQNXTDZ($A$1,$B12,H$1,$B$1)} -> 0 | I12: {=_xll.EQNXTDZ($A$1,$B12,I$1,$B$1)} -> 0 | J12: {=_xll.EQNXTDZ($A$1,$B12,J$1,$B$1)} -> 0 | ... AF12: {=_xll.EQNXTDZ($A$1,$B12,AF$1,$B$1)} -> 0
A13: Sales Turnover | B13: PL_TOTAL_GROSS_SALES | C13: {=_xll.EQNXTDZ($A$1,$B13,C$1,$B$1)} -> 0 | D13: {=_xll.EQNXTDZ($A$1,$B13,D$1,$B$1)} -> 0 | E13: {=_xll.EQNXTDZ($A$1,$B13,E$1,$B$1)} -> 0 | F13: {=_xll.EQNXTDZ($A$1,$B13,F$1,$B$1)} -> 0 | G13: {=_xll.EQNXTDZ($A$1,$B13,G$1,$B$1)} -> 0 | H13: {=_xll.EQNXTDZ($A$1,$B13,H$1,$B$1)} -> 0 | I13: {=_xll.EQNXTDZ($A$1,$B13,I$1,$B$1)} -> 0 | J13: {=_xll.EQNXTDZ($A$1,$B13,J$1,$B$1)} -> 0 | ... AF13: {=_xll.EQNXTDZ($A$1,$B13,AF$1,$B$1)} -> 0
A14: Net Sales | B14: PL_NET_SALES | C14: {=_xll.EQNXTDZ($A$1,$B14,C$1,$B$1)} -> 0 | D14: {=_xll.EQNXTDZ($A$1,$B14,D$1,$B$1)} -> 0 | E14: {=_xll.EQNXTDZ($A$1,$B14,E$1,$B$1)} -> 0 | F14: {=_xll.EQNXTDZ($A$1,$B14,F$1,$B$1)} -> 0 | G14: {=_xll.EQNXTDZ($A$1,$B14,G$1,$B$1)} -> 0 | H14: {=_xll.EQNXTDZ($A$1,$B14,H$1,$B$1)} -> 0 | I14: {=_xll.EQNXTDZ($A$1,$B14,I$1,$B$1)} -> 0 | J14: {=_xll.EQNXTDZ($A$1,$B14,J$1,$B$1)} -> 0 | ... AF14: {=_xll.EQNXTDZ($A$1,$B14,AF$1,$B$1)} -> 0
A15: Increase/Decrease in Stock | B15: PL_INC_DEC_INVENTORY | C15: {=_xll.EQNXTDZ($A$1,$B15,C$1,$B$1)} -> 0 | D15: {=_xll.EQNXTDZ($A$1,$B15,D$1,$B$1)} -> 0 | E15: {=_xll.EQNXTDZ($A$1,$B15,E$1,$B$1)} -> 0 | F15: {=_xll.EQNXTDZ($A$1,$B15,F$1,$B$1)} -> 0 | G15: {=_xll.EQNXTDZ($A$1,$B15,G$1,$B$1)} -> 0 | H15: {=_xll.EQNXTDZ($A$1,$B15,H$1,$B$1)} -> 0 | I15: {=_xll.EQNXTDZ($A$1,$B15,I$1,$B$1)} -> 0 | J15: {=_xll.EQNXTDZ($A$1,$B15,J$1,$B$1)} -> 0 | ... AF15: {=_xll.EQNXTDZ($A$1,$B15,AF$1,$B$1)} -> 0
A16: Raw Material Consumed | B16: PL_RAW_MATRS_CONSUMED | C16: {=_xll.EQNXTDZ($A$1,$B16,C$1,$B$1)} -> 0 | D16: {=_xll.EQNXTDZ($A$1,$B16,D$1,$B$1)} -> 0 | E16: {=_xll.EQNXTDZ($A$1,$B16,E$1,$B$1)} -> 0 | F16: {=_xll.EQNXTDZ($A$1,$B16,F$1,$B$1)} -> 0 | G16: {=_xll.EQNXTDZ($A$1,$B16,G$1,$B$1)} -> 0 | H16: {=_xll.EQNXTDZ($A$1,$B16,H$1,$B$1)} -> 0 | I16: {=_xll.EQNXTDZ($A$1,$B16,I$1,$B$1)} -> 0 | J16: {=_xll.EQNXTDZ($A$1,$B16,J$1,$B$1)} -> 0 | ... AF16: {=_xll.EQNXTDZ($A$1,$B16,AF$1,$B$1)} -> 0
A17: Power & Fuel Cost | B17: PL_POWER_FUEL | C17: {=_xll.EQNXTDZ($A$1,$B17,C$1,$B$1)} -> 0 | D17: {=_xll.EQNXTDZ($A$1,$B17,D$1,$B$1)} -> 0 | E17: {=_xll.EQNXTDZ($A$1,$B17,E$1,$B$1)} -> 0 | F17: {=_xll.EQNXTDZ($A$1,$B17,F$1,$B$1)} -> 0 | G17: {=_xll.EQNXTDZ($A$1,$B17,G$1,$B$1)} -> 0 | H17: {=_xll.EQNXTDZ($A$1,$B17,H$1,$B$1)} -> 0 | I17: {=_xll.EQNXTDZ($A$1,$B17,I$1,$B$1)} -> 0 | J17: {=_xll.EQNXTDZ($A$1,$B17,J$1,$B$1)} -> 0 | ... AF17: {=_xll.EQNXTDZ($A$1,$B17,AF$1,$B$1)} -> 0
A18: Employee Cost | B18: PL_EMPLOYEES | C18: {=_xll.EQNXTDZ($A$1,$B18,C$1,$B$1)} -> 0 | D18: {=_xll.EQNXTDZ($A$1,$B18,D$1,$B$1)} -> 0 | E18: {=_xll.EQNXTDZ($A$1,$B18,E$1,$B$1)} -> 0 | F18: {=_xll.EQNXTDZ($A$1,$B18,F$1,$B$1)} -> 0 | G18: {=_xll.EQNXTDZ($A$1,$B18,G$1,$B$1)} -> 0 | H18: {=_xll.EQNXTDZ($A$1,$B18,H$1,$B$1)} -> 0 | I18: {=_xll.EQNXTDZ($A$1,$B18,I$1,$B$1)} -> 0 | J18: {=_xll.EQNXTDZ($A$1,$B18,J$1,$B$1)} -> 0 | ... AF18: {=_xll.EQNXTDZ($A$1,$B18,AF$1,$B$1)} -> 0
A19: Operating & Manufacturing Expenses | B19: PL_GEN_OTHER_MFG_EXPS | C19: {=_xll.EQNXTDZ($A$1,$B19,C$1,$B$1)} -> 0 | D19: {=_xll.EQNXTDZ($A$1,$B19,D$1,$B$1)} -> 0 | E19: {=_xll.EQNXTDZ($A$1,$B19,E$1,$B$1)} -> 0 | F19: {=_xll.EQNXTDZ($A$1,$B19,F$1,$B$1)} -> 0 | G19: {=_xll.EQNXTDZ($A$1,$B19,G$1,$B$1)} -> 0 | H19: {=_xll.EQNXTDZ($A$1,$B19,H$1,$B$1)} -> 0 | I19: {=_xll.EQNXTDZ($A$1,$B19,I$1,$B$1)} -> 0 | J19: {=_xll.EQNXTDZ($A$1,$B19,J$1,$B$1)} -> 0 | ... AF19: {=_xll.EQNXTDZ($A$1,$B19,AF$1,$B$1)} -> 0
A20: Cost of Software development | B20: PL_COST_SW | C20: {=_xll.EQNXTDZ($A$1,$B20,C$1,$B$1)} -> 0 | D20: {=_xll.EQNXTDZ($A$1,$B20,D$1,$B$1)} -> 0 | E20: {=_xll.EQNXTDZ($A$1,$B20,E$1,$B$1)} -> 0 | F20: {=_xll.EQNXTDZ($A$1,$B20,F$1,$B$1)} -> 0 | G20: {=_xll.EQNXTDZ($A$1,$B20,G$1,$B$1)} -> 0 | H20: {=_xll.EQNXTDZ($A$1,$B20,H$1,$B$1)} -> 0 | I20: {=_xll.EQNXTDZ($A$1,$B20,I$1,$B$1)} -> 0 | J20: {=_xll.EQNXTDZ($A$1,$B20,J$1,$B$1)} -> 0 | ... AF20: {=_xll.EQNXTDZ($A$1,$B20,AF$1,$B$1)} -> 0
... A49: Consolidated Net Profit | B49: PLC_CONSOLIDATED_NETPROFIT | C49: {=_xll.EQNXTDZ($A$1,$B49,C$1,$B$1)} -> 0 | D49: {=_xll.EQNXTDZ($A$1,$B49,D$1,$B$1)} -> 0 | E49: {=_xll.EQNXTDZ($A$1,$B49,E$1,$B$1)} -> 0 | F49: {=_xll.EQNXTDZ($A$1,$B49,F$1,$B$1)} -> 0 | G49: {=_xll.EQNXTDZ($A$1,$B49,G$1,$B$1)} -> 0 | H49: {=_xll.EQNXTDZ($A$1,$B49,H$1,$B$1)} -> 0 | I49: {=_xll.EQNXTDZ($A$1,$B49,I$1,$B$1)} -> 0 | J49: {=_xll.EQNXTDZ($A$1,$B49,J$1,$B$1)} -> 0 | ... AF49: {=_xll.EQNXTDZ($A$1,$B49,AF$1,$B$1)} -> 0
A51: Field Description | B51: Field Name
A52: Equity Paid Up | B52: FH_EQUITY_PAIDUP | C52: {=_xll.EQNXTDZ($A$1,$B52,C$1,$B$1)} -> 0 | D52: {=_xll.EQNXTDZ($A$1,$B52,D$1,$B$1)} -> 0 | E52: {=_xll.EQNXTDZ($A$1,$B52,E$1,$B$1)} -> 0 | F52: {=_xll.EQNXTDZ($A$1,$B52,F$1,$B$1)} -> 0 | G52: {=_xll.EQNXTDZ($A$1,$B52,G$1,$B$1)} -> 0 | H52: {=_xll.EQNXTDZ($A$1,$B52,H$1,$B$1)} -> 0 | I52: {=_xll.EQNXTDZ($A$1,$B52,I$1,$B$1)} -> 0 | J52: {=_xll.EQNXTDZ($A$1,$B52,J$1,$B$1)} -> 0 | ... AF52: {=_xll.EQNXTDZ($A$1,$B52,AF$1,$B$1)} -> 0
A53: Reserves and Surplus | B53: FH_RESERVE | C53: {=_xll.EQNXTDZ($A$1,$B53,C$1,$B$1)} -> 0 | D53: {=_xll.EQNXTDZ($A$1,$B53,D$1,$B$1)} -> 0 | E53: {=_xll.EQNXTDZ($A$1,$B53,E$1,$B$1)} -> 0 | F53: {=_xll.EQNXTDZ($A$1,$B53,F$1,$B$1)} -> 0 | G53: {=_xll.EQNXTDZ($A$1,$B53,G$1,$B$1)} -> 0 | H53: {=_xll.EQNXTDZ($A$1,$B53,H$1,$B$1)} -> 0 | I53: {=_xll.EQNXTDZ($A$1,$B53,I$1,$B$1)} -> 0 | J53: {=_xll.EQNXTDZ($A$1,$B53,J$1,$B$1)} -> 0 | ... AF53: {=_xll.EQNXTDZ($A$1,$B53,AF$1,$B$1)} -> 0
A54: Net Worth | B54: FH_NET_WORTH | C54: {=_xll.EQNXTDZ($A$1,$B54,C$1,$B$1)} -> 0 | D54: {=_xll.EQNXTDZ($A$1,$B54,D$1,$B$1)} -> 0 | E54: {=_xll.EQNXTDZ($A$1,$B54,E$1,$B$1)} -> 0 | F54: {=_xll.EQNXTDZ($A$1,$B54,F$1,$B$1)} -> 0 | G54: {=_xll.EQNXTDZ($A$1,$B54,G$1,$B$1)} -> 0 | H54: {=_xll.EQNXTDZ($A$1,$B54,H$1,$B$1)} -> 0 | I54: {=_xll.EQNXTDZ($A$1,$B54,I$1,$B$1)} -> 0 | J54: {=_xll.EQNXTDZ($A$1,$B54,J$1,$B$1)} -> 0 | ... AF54: {=_xll.EQNXTDZ($A$1,$B54,AF$1,$B$1)} -> 0
A55: Total Debt | B55: FH_TOTAL_DEBTS | C55: {=_xll.EQNXTDZ($A$1,$B55,C$1,$B$1)} -> 0 | D55: {=_xll.EQNXTDZ($A$1,$B55,D$1,$B$1)} -> 0 | E55: {=_xll.EQNXTDZ($A$1,$B55,E$1,$B$1)} -> 0 | F55: {=_xll.EQNXTDZ($A$1,$B55,F$1,$B$1)} -> 0 | G55: {=_xll.EQNXTDZ($A$1,$B55,G$1,$B$1)} -> 0 | H55: {=_xll.EQNXTDZ($A$1,$B55,H$1,$B$1)} -> 0 | I55: {=_xll.EQNXTDZ($A$1,$B55,I$1,$B$1)} -> 0 | J55: {=_xll.EQNXTDZ($A$1,$B55,J$1,$B$1)} -> 0 | ... AF55: {=_xll.EQNXTDZ($A$1,$B55,AF$1,$B$1)} -> 0
A56: Deposits | B56: FH_DEPOSITS | C56: {=_xll.EQNXTDZ($A$1,$B56,C$1,$B$1)} -> 0 | D56: {=_xll.EQNXTDZ($A$1,$B56,D$1,$B$1)} -> 0 | E56: {=_xll.EQNXTDZ($A$1,$B56,E$1,$B$1)} -> 0 | F56: {=_xll.EQNXTDZ($A$1,$B56,F$1,$B$1)} -> 0 | G56: {=_xll.EQNXTDZ($A$1,$B56,G$1,$B$1)} -> 0 | H56: {=_xll.EQNXTDZ($A$1,$B56,H$1,$B$1)} -> 0 | I56: {=_xll.EQNXTDZ($A$1,$B56,I$1,$B$1)} -> 0 | J56: {=_xll.EQNXTDZ($A$1,$B56,J$1,$B$1)} -> 0 | ... AF56: {=_xll.EQNXTDZ($A$1,$B56,AF$1,$B$1)} -> 0
A57: Borrowings | B57: FH_BORROWINGS | C57: {=_xll.EQNXTDZ($A$1,$B57,C$1,$B$1)} -> 0 | D57: {=_xll.EQNXTDZ($A$1,$B57,D$1,$B$1)} -> 0 | E57: {=_xll.EQNXTDZ($A$1,$B57,E$1,$B$1)} -> 0 | F57: {=_xll.EQNXTDZ($A$1,$B57,F$1,$B$1)} -> 0 | G57: {=_xll.EQNXTDZ($A$1,$B57,G$1,$B$1)} -> 0 | H57: {=_xll.EQNXTDZ($A$1,$B57,H$1,$B$1)} -> 0 | I57: {=_xll.EQNXTDZ($A$1,$B57,I$1,$B$1)} -> 0 | J57: {=_xll.EQNXTDZ($A$1,$B57,J$1,$B$1)} -> 0 | ... AF57: {=_xll.EQNXTDZ($A$1,$B57,AF$1,$B$1)} -> 0
A58: Month End | B58: BMONTH_MONTHEND | C58: {=_xll.EQNXTDZ($A$1,$B58,C$1,$B$1)} -> 0 | D58: {=_xll.EQNXTDZ($A$1,$B58,D$1,$B$1)} -> 0 | E58: {=_xll.EQNXTDZ($A$1,$B58,E$1,$B$1)} -> 0 | F58: {=_xll.EQNXTDZ($A$1,$B58,F$1,$B$1)} -> 0 | G58: {=_xll.EQNXTDZ($A$1,$B58,G$1,$B$1)} -> 0 | H58: {=_xll.EQNXTDZ($A$1,$B58,H$1,$B$1)} -> 0 | I58: {=_xll.EQNXTDZ($A$1,$B58,I$1,$B$1)} -> 0 | J58: {=_xll.EQNXTDZ($A$1,$B58,J$1,$B$1)} -> 0 | ... AF58: {=_xll.EQNXTDZ($A$1,$B58,AF$1,$B$1)} -> 0
A59: Close Price (Unit Curr.) | B59: FH_YEAR_PRICE | C59: {=_xll.EQNXTDZ($A$1,$B59,C$1,$B$1)} -> 0 | D59: {=_xll.EQNXTDZ($A$1,$B59,D$1,$B$1)} -> 0 | E59: {=_xll.EQNXTDZ($A$1,$B59,E$1,$B$1)} -> 0 | F59: {=_xll.EQNXTDZ($A$1,$B59,F$1,$B$1)} -> 0 | G59: {=_xll.EQNXTDZ($A$1,$B59,G$1,$B$1)} -> 0 | H59: {=_xll.EQNXTDZ($A$1,$B59,H$1,$B$1)} -> 0 | I59: {=_xll.EQNXTDZ($A$1,$B59,I$1,$B$1)} -> 0 | J59: {=_xll.EQNXTDZ($A$1,$B59,J$1,$B$1)} -> 0 | ... AF59: {=_xll.EQNXTDZ($A$1,$B59,AF$1,$B$1)} -> 0
A60: High Price (Unit Curr.) | B60: FH_HIGH | C60: {=_xll.EQNXTDZ($A$1,$B60,C$1,$B$1)} -> 0 | D60: {=_xll.EQNXTDZ($A$1,$B60,D$1,$B$1)} -> 0 | E60: {=_xll.EQNXTDZ($A$1,$B60,E$1,$B$1)} -> 0 | F60: {=_xll.EQNXTDZ($A$1,$B60,F$1,$B$1)} -> 0 | G60: {=_xll.EQNXTDZ($A$1,$B60,G$1,$B$1)} -> 0 | H60: {=_xll.EQNXTDZ($A$1,$B60,H$1,$B$1)} -> 0 | I60: {=_xll.EQNXTDZ($A$1,$B60,I$1,$B$1)} -> 0 | J60: {=_xll.EQNXTDZ($A$1,$B60,J$1,$B$1)} -> 0 | ... AF60: {=_xll.EQNXTDZ($A$1,$B60,AF$1,$B$1)} -> 0
A61: Low Price (Unit Curr.) | B61: FH_LOW | C61: {=_xll.EQNXTDZ($A$1,$B61,C$1,$B$1)} -> 0 | D61: {=_xll.EQNXTDZ($A$1,$B61,D$1,$B$1)} -> 0 | E61: {=_xll.EQNXTDZ($A$1,$B61,E$1,$B$1)} -> 0 | F61: {=_xll.EQNXTDZ($A$1,$B61,F$1,$B$1)} -> 0 | G61: {=_xll.EQNXTDZ($A$1,$B61,G$1,$B$1)} -> 0 | H61: {=_xll.EQNXTDZ($A$1,$B61,H$1,$B$1)} -> 0 | I61: {=_xll.EQNXTDZ($A$1,$B61,I$1,$B$1)} -> 0 | J61: {=_xll.EQNXTDZ($A$1,$B61,J$1,$B$1)} -> 0 | ... AF61: {=_xll.EQNXTDZ($A$1,$B61,AF$1,$B$1)} -> 0
A62: Month end date | B62: BMONTH_CLOSEDATE | C62: {=_xll.EQNXTDZ($A$1,$B62,C$1,$B$1)} -> 0 | D62: {=_xll.EQNXTDZ($A$1,$B62,D$1,$B$1)} -> 0 | E62: {=_xll.EQNXTDZ($A$1,$B62,E$1,$B$1)} -> 0 | F62: {=_xll.EQNXTDZ($A$1,$B62,F$1,$B$1)} -> 0 | G62: {=_xll.EQNXTDZ($A$1,$B62,G$1,$B$1)} -> 0 | H62: {=_xll.EQNXTDZ($A$1,$B62,H$1,$B$1)} -> 0 | I62: {=_xll.EQNXTDZ($A$1,$B62,I$1,$B$1)} -> 0 | J62: {=_xll.EQNXTDZ($A$1,$B62,J$1,$B$1)} -> 0 | ... AF62: {=_xll.EQNXTDZ($A$1,$B62,AF$1,$B$1)} -> 0
A63: Volume ('000) | B63: BMONTH_VOLUME | C63: {=_xll.EQNXTDZ($A$1,$B63,C$1,$B$1)} -> 0 | D63: {=_xll.EQNXTDZ($A$1,$B63,D$1,$B$1)} -> 0 | E63: {=_xll.EQNXTDZ($A$1,$B63,E$1,$B$1)} -> 0 | F63: {=_xll.EQNXTDZ($A$1,$B63,F$1,$B$1)} -> 0 | G63: {=_xll.EQNXTDZ($A$1,$B63,G$1,$B$1)} -> 0 | H63: {=_xll.EQNXTDZ($A$1,$B63,H$1,$B$1)} -> 0 | I63: {=_xll.EQNXTDZ($A$1,$B63,I$1,$B$1)} -> 0 | J63: {=_xll.EQNXTDZ($A$1,$B63,J$1,$B$1)} -> 0 | ... AF63: {=_xll.EQNXTDZ($A$1,$B63,AF$1,$B$1)} -> 0
... A68: NIM_Reported (%) | B68: RBI_NIMAR | C68: {=_xll.EQNXTDZ($A$1,$B68,C$1,$B$1)} -> 0 | D68: {=_xll.EQNXTDZ($A$1,$B68,D$1,$B$1)} -> 0 | E68: {=_xll.EQNXTDZ($A$1,$B68,E$1,$B$1)} -> 0 | F68: {=_xll.EQNXTDZ($A$1,$B68,F$1,$B$1)} -> 0 | G68: {=_xll.EQNXTDZ($A$1,$B68,G$1,$B$1)} -> 0 | H68: {=_xll.EQNXTDZ($A$1,$B68,H$1,$B$1)} -> 0 | I68: {=_xll.EQNXTDZ($A$1,$B68,I$1,$B$1)} -> 0 | J68: {=_xll.EQNXTDZ($A$1,$B68,J$1,$B$1)} -> 0 | ... AF68: {=_xll.EQNXTDZ($A$1,$B68,AF$1,$B$1)} -> 0
A70: Assets | C70: =+C85+C105+C107-C108-C109+C111+C112+C114+C115+C116+C117+C118+C120+C121+C122+C123+C124+C125+C126+C106+C113 -> 0 | D70: =+D85+D105+D107-D108-D109+D111+D112+D114+D115+D116+D117+D118+D120+D121+D122+D123+D124+D125+D126+D106+D113 -> 0 | E70: =+E85+E105+E107-E108-E109+E111+E112+E114+E115+E116+E117+E118+E120+E121+E122+E123+E124+E125+E126+E106+E113 -> 0 | F70: =+F85+F105+F107-F108-F109+F111+F112+F114+F115+F116+F117+F118+F120+F121+F122+F123+F124+F125+F126+F106+F113 -> 0 | G70: =+G85+G105+G107-G108-G109+G111+G112+G114+G115+G116+G117+G118+G120+G121+G122+G123+G124+G125+G126+G106+G113 -> 0 | H70: =+H85+H105+H107-H108-H109+H111+H112+H114+H115+H116+H117+H118+H120+H121+H122+H123+H124+H125+H126+H106+H113 -> 0 | I70: =+I85+I105+I107-I108-I109+I111+I112+I114+I115+I116+I117+I118+I120+I121+I122+I123+I124+I125+I126+I106+I113 -> 0 | J70: =+J85+J105+J107-J108-J109+J111+J112+J114+J115+J116+J117+J118+J120+J121+J122+J123+J124+J125+J126+J106+J113 -> 0 | ... AF70: =+AF85+AF105+AF107-AF108-AF109+AF111+AF112+AF114+AF115+AF116+AF117+AF118+AF120+AF121+AF122+AF123+AF124+AF125+AF126+AF106+AF113 -> 0
A71: Liab | C71: =+C77+C78+C79+C81+C82+C83+C84+C86+C87+C88+C89+C90+C91+C93+C94+C100+C101+C102 -> 0 | D71: =+D77+D78+D79+D81+D82+D83+D84+D86+D87+D88+D89+D90+D91+D93+D94+D100+D101+D102 -> 0 | E71: =+E77+E78+E79+E81+E82+E83+E84+E86+E87+E88+E89+E90+E91+E93+E94+E100+E101+E102 -> 0 | F71: =+F77+F78+F79+F81+F82+F83+F84+F86+F87+F88+F89+F90+F91+F93+F94+F100+F101+F102 -> 0 | G71: =+G77+G78+G79+G81+G82+G83+G84+G86+G87+G88+G89+G90+G91+G93+G94+G100+G101+G102 -> 0 | H71: =+H77+H78+H79+H81+H82+H83+H84+H86+H87+H88+H89+H90+H91+H93+H94+H100+H101+H102 -> 0 | I71: =+I77+I78+I79+I81+I82+I83+I84+I86+I87+I88+I89+I90+I91+I93+I94+I100+I101+I102 -> 0 | J71: =+J77+J78+J79+J81+J82+J83+J84+J86+J87+J88+J89+J90+J91+J93+J94+J100+J101+J102 -> 0 | ... AF71: =+AF77+AF78+AF79+AF81+AF82+AF83+AF84+AF86+AF87+AF88+AF89+AF90+AF91+AF93+AF94+AF100+AF101+AF102 -> 0
A72: Field Description | B72: Field Name
A73: Year End | B73: BBS_YEAR_END | C73: {=_xll.EQNXTDZ($A$1,$B73,C$1,$B$1)} -> 0 | D73: {=_xll.EQNXTDZ($A$1,$B73,D$1,$B$1)} -> 0 | E73: {=_xll.EQNXTDZ($A$1,$B73,E$1,$B$1)} -> 0 | F73: {=_xll.EQNXTDZ($A$1,$B73,F$1,$B$1)} -> 0 | G73: {=_xll.EQNXTDZ($A$1,$B73,G$1,$B$1)} -> 0 | H73: {=_xll.EQNXTDZ($A$1,$B73,H$1,$B$1)} -> 0 | I73: {=_xll.EQNXTDZ($A$1,$B73,I$1,$B$1)} -> 0 | J73: {=_xll.EQNXTDZ($A$1,$B73,J$1,$B$1)} -> 0 | ... AF73: {=_xll.EQNXTDZ($A$1,$B73,AF$1,$B$1)} -> 0
A74: Year | B74: BBS_YEAR | C74: {=_xll.EQNXTDZ($A$1,$B74,C$1,$B$1)} -> 0 | D74: {=_xll.EQNXTDZ($A$1,$B74,D$1,$B$1)} -> 0 | E74: {=_xll.EQNXTDZ($A$1,$B74,E$1,$B$1)} -> 0 | F74: {=_xll.EQNXTDZ($A$1,$B74,F$1,$B$1)} -> 0 | G74: {=_xll.EQNXTDZ($A$1,$B74,G$1,$B$1)} -> 0 | H74: {=_xll.EQNXTDZ($A$1,$B74,H$1,$B$1)} -> 0 | I74: {=_xll.EQNXTDZ($A$1,$B74,I$1,$B$1)} -> 0 | J74: {=_xll.EQNXTDZ($A$1,$B74,J$1,$B$1)} -> 0 | ... AF74: {=_xll.EQNXTDZ($A$1,$B74,AF$1,$B$1)} -> 0
A75: No of Months | B75: BBS_NO_MONTHS | C75: {=_xll.EQNXTDZ($A$1,$B75,C$1,$B$1)} -> 0 | D75: {=_xll.EQNXTDZ($A$1,$B75,D$1,$B$1)} -> 0 | E75: {=_xll.EQNXTDZ($A$1,$B75,E$1,$B$1)} -> 0 | F75: {=_xll.EQNXTDZ($A$1,$B75,F$1,$B$1)} -> 0 | G75: {=_xll.EQNXTDZ($A$1,$B75,G$1,$B$1)} -> 0 | H75: {=_xll.EQNXTDZ($A$1,$B75,H$1,$B$1)} -> 0 | I75: {=_xll.EQNXTDZ($A$1,$B75,I$1,$B$1)} -> 0 | J75: {=_xll.EQNXTDZ($A$1,$B75,J$1,$B$1)} -> 0 | ... AF75: {=_xll.EQNXTDZ($A$1,$B75,AF$1,$B$1)} -> 0
...

Sheet QTR Raw
A1: =+'Annual Raw'!A1 -> 0 | B1: X | C1: 201503 | D1: 201506 | E1: 201509 | F1: 201512 | G1: 201603 | H1: 201606 | I1: 201609 | J1: 201612 | K1: 201703 | L1: 201706 | M1: 201709 | N1: 201712 | O1: 201803 | P1: 201806 | Q1: 201809 | R1: 201812 | S1: 201903 | T1: 201906 | U1: 201909 | V1: 201912 | W1: 202003 | X1: 202006 | Y1: 202009 | Z1: 202012 | AA1: 202103 | AB1: 202106 | AC1: 202109 | AD1: 202112 | AE1: 202203 | AF1: 202206 | AG1: 202209 | AH1: 202212 | AI1: 202303 | AJ1: 202306 | AK1: 202309 | AL1: 202312 | AM1: 202403 | AN1: 202406 | AO1: 202409 | AP1: 202412 | AQ1: 202503 | AR1: 202506 | AS1: 202509 | AT1: 202512 | AU1: 202603 | AV1: 202606 | AW1: 202609 | AX1: 202612 | AY1: 202703 | AZ1: 202706 | BA1: 202709 | BB1: 202712 | BC1: 202803 | BD1: 202806 | BE1: 202809 | BF1: 202812 | BG1: 202903 | BH1: 202906 | BI1: 202909 | BJ1: 202912 | BK1: 203003
A4: Field Description | B4: Field Name
A5: Date End | B5: BQTR_DATE_END | C5: {=+_xll.EQNXTDZ($A$1,$B5,C$1,$B$1)} -> 0 | D5: {=+_xll.EQNXTDZ($A$1,$B5,D$1,$B$1)} -> 0 | E5: {=+_xll.EQNXTDZ($A$1,$B5,E$1,$B$1)} -> 0 | F5: {=+_xll.EQNXTDZ($A$1,$B5,F$1,$B$1)} -> 0 | G5: {=+_xll.EQNXTDZ($A$1,$B5,G$1,$B$1)} -> 0 | H5: {=+_xll.EQNXTDZ($A$1,$B5,H$1,$B$1)} -> 0 | I5: {=+_xll.EQNXTDZ($A$1,$B5,I$1,$B$1)} -> 0 | J5: {=+_xll.EQNXTDZ($A$1,$B5,J$1,$B$1)} -> 0 | ... BK5: {=+_xll.EQNXTDZ($A$1,$B5,BK$1,$B$1)} -> 0
A6: Field Description | B6: Field Name
A7: Date End | B7: QTR_DATE_END | C7: {=+_xll.EQNXTDZ($A$1,$B7,C$1,$B$1)} -> 0 | D7: {=+_xll.EQNXTDZ($A$1,$B7,D$1,$B$1)} -> 0 | E7: {=+_xll.EQNXTDZ($A$1,$B7,E$1,$B$1)} -> 0 | F7: {=+_xll.EQNXTDZ($A$1,$B7,F$1,$B$1)} -> 0 | G7: {=+_xll.EQNXTDZ($A$1,$B7,G$1,$B$1)} -> 0 | H7: {=+_xll.EQNXTDZ($A$1,$B7,H$1,$B$1)} -> 0 | I7: {=+_xll.EQNXTDZ($A$1,$B7,I$1,$B$1)} -> 0 | J7: {=+_xll.EQNXTDZ($A$1,$B7,J$1,$B$1)} -> 0 | ... BK7: {=+_xll.EQNXTDZ($A$1,$B7,BK$1,$B$1)} -> 0
A8: Gross Sales | B8: QTR_GROSS_SALE | C8: {=+_xll.EQNXTDZ($A$1,$B8,C$1,$B$1)} -> 0 | D8: {=+_xll.EQNXTDZ($A$1,$B8,D$1,$B$1)} -> 0 | E8: {=+_xll.EQNXTDZ($A$1,$B8,E$1,$B$1)} -> 0 | F8: {=+_xll.EQNXTDZ($A$1,$B8,F$1,$B$1)} -> 0 | G8: {=+_xll.EQNXTDZ($A$1,$B8,G$1,$B$1)} -> 0 | H8: {=+_xll.EQNXTDZ($A$1,$B8,H$1,$B$1)} -> 0 | I8: {=+_xll.EQNXTDZ($A$1,$B8,I$1,$B$1)} -> 0 | J8: {=+_xll.EQNXTDZ($A$1,$B8,J$1,$B$1)} -> 0 | ... BK8: {=+_xll.EQNXTDZ($A$1,$B8,BK$1,$B$1)} -> 0
A9: Net Sales | B9: QTR_OTHER_NETSALES | C9: {=+_xll.EQNXTDZ($A$1,$B9,C$1,$B$1)} -> 0 | D9: {=+_xll.EQNXTDZ($A$1,$B9,D$1,$B$1)} -> 0 | E9: {=+_xll.EQNXTDZ($A$1,$B9,E$1,$B$1)} -> 0 | F9: {=+_xll.EQNXTDZ($A$1,$B9,F$1,$B$1)} -> 0 | G9: {=+_xll.EQNXTDZ($A$1,$B9,G$1,$B$1)} -> 0 | H9: {=+_xll.EQNXTDZ($A$1,$B9,H$1,$B$1)} -> 0 | I9: {=+_xll.EQNXTDZ($A$1,$B9,I$1,$B$1)} -> 0 | J9: {=+_xll.EQNXTDZ($A$1,$B9,J$1,$B$1)} -> 0 | ... BK9: {=+_xll.EQNXTDZ($A$1,$B9,BK$1,$B$1)} -> 0
A10: Share of Associates | B10: QTR_SHARE_ASSOCIATE_REVENUE | C10: {=+_xll.EQNXTDZ($A$1,$B10,C$1,$B$1)} -> 0 | D10: {=+_xll.EQNXTDZ($A$1,$B10,D$1,$B$1)} -> 0 | E10: {=+_xll.EQNXTDZ($A$1,$B10,E$1,$B$1)} -> 0 | F10: {=+_xll.EQNXTDZ($A$1,$B10,F$1,$B$1)} -> 0 | G10: {=+_xll.EQNXTDZ($A$1,$B10,G$1,$B$1)} -> 0 | H10: {=+_xll.EQNXTDZ($A$1,$B10,H$1,$B$1)} -> 0 | I10: {=+_xll.EQNXTDZ($A$1,$B10,I$1,$B$1)} -> 0 | J10: {=+_xll.EQNXTDZ($A$1,$B10,J$1,$B$1)} -> 0 | ... BK10: {=+_xll.EQNXTDZ($A$1,$B10,BK$1,$B$1)} -> 0
A11: Other operating income | B11: QTR_JOB_WORKS | C11: {=+_xll.EQNXTDZ($A$1,$B11,C$1,$B$1)} -> 0 | D11: {=+_xll.EQNXTDZ($A$1,$B11,D$1,$B$1)} -> 0 | E11: {=+_xll.EQNXTDZ($A$1,$B11,E$1,$B$1)} -> 0 | F11: {=+_xll.EQNXTDZ($A$1,$B11,F$1,$B$1)} -> 0 | G11: {=+_xll.EQNXTDZ($A$1,$B11,G$1,$B$1)} -> 0 | H11: {=+_xll.EQNXTDZ($A$1,$B11,H$1,$B$1)} -> 0 | I11: {=+_xll.EQNXTDZ($A$1,$B11,I$1,$B$1)} -> 0 | J11: {=+_xll.EQNXTDZ($A$1,$B11,J$1,$B$1)} -> 0 | ... BK11: {=+_xll.EQNXTDZ($A$1,$B11,BK$1,$B$1)} -> 0
A12: Income on Investments | B12: QTR_INC_INV | C12: {=+_xll.EQNXTDZ($A$1,$B12,C$1,$B$1)} -> 0 | D12: {=+_xll.EQNXTDZ($A$1,$B12,D$1,$B$1)} -> 0 | E12: {=+_xll.EQNXTDZ($A$1,$B12,E$1,$B$1)} -> 0 | F12: {=+_xll.EQNXTDZ($A$1,$B12,F$1,$B$1)} -> 0 | G12: {=+_xll.EQNXTDZ($A$1,$B12,G$1,$B$1)} -> 0 | H12: {=+_xll.EQNXTDZ($A$1,$B12,H$1,$B$1)} -> 0 | I12: {=+_xll.EQNXTDZ($A$1,$B12,I$1,$B$1)} -> 0 | J12: {=+_xll.EQNXTDZ($A$1,$B12,J$1,$B$1)} -> 0 | ... BK12: {=+_xll.EQNXTDZ($A$1,$B12,BK$1,$B$1)} -> 0
A13: Net Sales & Other Operating Income | B13: QTR_NET_SALES | C13: {=+_xll.EQNXTDZ($A$1,$B13,C$1,$B$1)} -> 0 | D13: {=+_xll.EQNXTDZ($A$1,$B13,D$1,$B$1)} -> 0 | E13: {=+_xll.EQNXTDZ($A$1,$B13,E$1,$B$1)} -> 0 | F13: {=+_xll.EQNXTDZ($A$1,$B13,F$1,$B$1)} -> 0 | G13: {=+_xll.EQNXTDZ($A$1,$B13,G$1,$B$1)} -> 0 | H13: {=+_xll.EQNXTDZ($A$1,$B13,H$1,$B$1)} -> 0 | I13: {=+_xll.EQNXTDZ($A$1,$B13,I$1,$B$1)} -> 0 | J13: {=+_xll.EQNXTDZ($A$1,$B13,J$1,$B$1)} -> 0 | ... BK13: {=+_xll.EQNXTDZ($A$1,$B13,BK$1,$B$1)} -> 0
A14: Interest Expended | B14: QTR_INTEREST_EX | C14: {=+_xll.EQNXTDZ($A$1,$B14,C$1,$B$1)} -> 0 | D14: {=+_xll.EQNXTDZ($A$1,$B14,D$1,$B$1)} -> 0 | E14: {=+_xll.EQNXTDZ($A$1,$B14,E$1,$B$1)} -> 0 | F14: {=+_xll.EQNXTDZ($A$1,$B14,F$1,$B$1)} -> 0 | G14: {=+_xll.EQNXTDZ($A$1,$B14,G$1,$B$1)} -> 0 | H14: {=+_xll.EQNXTDZ($A$1,$B14,H$1,$B$1)} -> 0 | I14: {=+_xll.EQNXTDZ($A$1,$B14,I$1,$B$1)} -> 0 | J14: {=+_xll.EQNXTDZ($A$1,$B14,J$1,$B$1)} -> 0 | ... BK14: {=+_xll.EQNXTDZ($A$1,$B14,BK$1,$B$1)} -> 0
A15: Operating & Manufacturing Expenses | B15: QTR_MFG_EXPS | C15: {=+_xll.EQNXTDZ($A$1,$B15,C$1,$B$1)} -> 0 | D15: {=+_xll.EQNXTDZ($A$1,$B15,D$1,$B$1)} -> 0 | E15: {=+_xll.EQNXTDZ($A$1,$B15,E$1,$B$1)} -> 0 | F15: {=+_xll.EQNXTDZ($A$1,$B15,F$1,$B$1)} -> 0 | G15: {=+_xll.EQNXTDZ($A$1,$B15,G$1,$B$1)} -> 0 | H15: {=+_xll.EQNXTDZ($A$1,$B15,H$1,$B$1)} -> 0 | I15: {=+_xll.EQNXTDZ($A$1,$B15,I$1,$B$1)} -> 0 | J15: {=+_xll.EQNXTDZ($A$1,$B15,J$1,$B$1)} -> 0 | ... BK15: {=+_xll.EQNXTDZ($A$1,$B15,BK$1,$B$1)} -> 0
A16: (Increase) / Decrease In Stocks | B16: QTR_INC_DEC_INVENTORY | C16: {=+_xll.EQNXTDZ($A$1,$B16,C$1,$B$1)} -> 0 | D16: {=+_xll.EQNXTDZ($A$1,$B16,D$1,$B$1)} -> 0 | E16: {=+_xll.EQNXTDZ($A$1,$B16,E$1,$B$1)} -> 0 | F16: {=+_xll.EQNXTDZ($A$1,$B16,F$1,$B$1)} -> 0 | G16: {=+_xll.EQNXTDZ($A$1,$B16,G$1,$B$1)} -> 0 | H16: {=+_xll.EQNXTDZ($A$1,$B16,H$1,$B$1)} -> 0 | I16: {=+_xll.EQNXTDZ($A$1,$B16,I$1,$B$1)} -> 0 | J16: {=+_xll.EQNXTDZ($A$1,$B16,J$1,$B$1)} -> 0 | ... BK16: {=+_xll.EQNXTDZ($A$1,$B16,BK$1,$B$1)} -> 0
A17: Cost of Services & Raw Materials | B17: QTR_RAW_MATERIAL_COST | C17: {=+_xll.EQNXTDZ($A$1,$B17,C$1,$B$1)} -> 0 | D17: {=+_xll.EQNXTDZ($A$1,$B17,D$1,$B$1)} -> 0 | E17: {=+_xll.EQNXTDZ($A$1,$B17,E$1,$B$1)} -> 0 | F17: {=+_xll.EQNXTDZ($A$1,$B17,F$1,$B$1)} -> 0 | G17: {=+_xll.EQNXTDZ($A$1,$B17,G$1,$B$1)} -> 0 | H17: {=+_xll.EQNXTDZ($A$1,$B17,H$1,$B$1)} -> 0 | I17: {=+_xll.EQNXTDZ($A$1,$B17,I$1,$B$1)} -> 0 | J17: {=+_xll.EQNXTDZ($A$1,$B17,J$1,$B$1)} -> 0 | ... BK17: {=+_xll.EQNXTDZ($A$1,$B17,BK$1,$B$1)} -> 0
A18: Purchase of Finished Goods | B18: QTR_PURCHASE_FIN_GOOD | C18: {=+_xll.EQNXTDZ($A$1,$B18,C$1,$B$1)} -> 0 | D18: {=+_xll.EQNXTDZ($A$1,$B18,D$1,$B$1)} -> 0 | E18: {=+_xll.EQNXTDZ($A$1,$B18,E$1,$B$1)} -> 0 | F18: {=+_xll.EQNXTDZ($A$1,$B18,F$1,$B$1)} -> 0 | G18: {=+_xll.EQNXTDZ($A$1,$B18,G$1,$B$1)} -> 0 | H18: {=+_xll.EQNXTDZ($A$1,$B18,H$1,$B$1)} -> 0 | I18: {=+_xll.EQNXTDZ($A$1,$B18,I$1,$B$1)} -> 0 | J18: {=+_xll.EQNXTDZ($A$1,$B18,J$1,$B$1)} -> 0 | ... BK18: {=+_xll.EQNXTDZ($A$1,$B18,BK$1,$B$1)} -> 0
... A47: Face Value | B47: QTR_FV | C47: {=+_xll.EQNXTDZ($A$1,$B47,C$1,$B$1)} -> 0 | D47: {=+_xll.EQNXTDZ($A$1,$B47,D$1,$B$1)} -> 0 | E47: {=+_xll.EQNXTDZ($A$1,$B47,E$1,$B$1)} -> 0 | F47: {=+_xll.EQNXTDZ($A$1,$B47,F$1,$B$1)} -> 0 | G47: {=+_xll.EQNXTDZ($A$1,$B47,G$1,$B$1)} -> 0 | H47: {=+_xll.EQNXTDZ($A$1,$B47,H$1,$B$1)} -> 0 | I47: {=+_xll.EQNXTDZ($A$1,$B47,I$1,$B$1)} -> 0 | J47: {=+_xll.EQNXTDZ($A$1,$B47,J$1,$B$1)} -> 0 | ... BK47: {=+_xll.EQNXTDZ($A$1,$B47,BK$1,$B$1)} -> 0
A50: Field Description | B50: Field Name
A51: Equity Paid Up | B51: QTR_EQUITY_CAP | C51: {=+_xll.EQNXTDZ($A$1,$B51,C$1,$B$1)} -> 0 | D51: {=+_xll.EQNXTDZ($A$1,$B51,D$1,$B$1)} -> 0 | E51: {=+_xll.EQNXTDZ($A$1,$B51,E$1,$B$1)} -> 0 | F51: {=+_xll.EQNXTDZ($A$1,$B51,F$1,$B$1)} -> 0 | G51: {=+_xll.EQNXTDZ($A$1,$B51,G$1,$B$1)} -> 0 | H51: {=+_xll.EQNXTDZ($A$1,$B51,H$1,$B$1)} -> 0 | I51: {=+_xll.EQNXTDZ($A$1,$B51,I$1,$B$1)} -> 0 | J51: {=+_xll.EQNXTDZ($A$1,$B51,J$1,$B$1)} -> 0 | ... BK51: {=+_xll.EQNXTDZ($A$1,$B51,BK$1,$B$1)} -> 0
A52: Face value | B52: QTR_FV | C52: {=+_xll.EQNXTDZ($A$1,$B52,C$1,$B$1)} -> 0 | D52: {=+_xll.EQNXTDZ($A$1,$B52,D$1,$B$1)} -> 0 | E52: {=+_xll.EQNXTDZ($A$1,$B52,E$1,$B$1)} -> 0 | F52: {=+_xll.EQNXTDZ($A$1,$B52,F$1,$B$1)} -> 0 | G52: {=+_xll.EQNXTDZ($A$1,$B52,G$1,$B$1)} -> 0 | H52: {=+_xll.EQNXTDZ($A$1,$B52,H$1,$B$1)} -> 0 | I52: {=+_xll.EQNXTDZ($A$1,$B52,I$1,$B$1)} -> 0 | J52: {=+_xll.EQNXTDZ($A$1,$B52,J$1,$B$1)} -> 0 | ... BK52: {=+_xll.EQNXTDZ($A$1,$B52,BK$1,$B$1)} -> 0
A55: Share Capital | B55: QTRB_SHARE_CAPITAL | C55: {=+_xll.EQNXTDZ($A$1,$B55,C$1,$B$1)} -> 0 | D55: {=+_xll.EQNXTDZ($A$1,$B55,D$1,$B$1)} -> 0 | E55: {=+_xll.EQNXTDZ($A$1,$B55,E$1,$B$1)} -> 0 | F55: {=+_xll.EQNXTDZ($A$1,$B55,F$1,$B$1)} -> 0 | G55: {=+_xll.EQNXTDZ($A$1,$B55,G$1,$B$1)} -> 0 | H55: {=+_xll.EQNXTDZ($A$1,$B55,H$1,$B$1)} -> 0 | I55: {=+_xll.EQNXTDZ($A$1,$B55,I$1,$B$1)} -> 0 | J55: {=+_xll.EQNXTDZ($A$1,$B55,J$1,$B$1)} -> 0 | ... BK55: {=+_xll.EQNXTDZ($A$1,$B55,BK$1,$B$1)} -> 0
A56: Share Warrants & outstandings | B56: QTRB_SHAREWARNDOUT | C56: {=+_xll.EQNXTDZ($A$1,$B56,C$1,$B$1)} -> 0 | D56: {=+_xll.EQNXTDZ($A$1,$B56,D$1,$B$1)} -> 0 | E56: {=+_xll.EQNXTDZ($A$1,$B56,E$1,$B$1)} -> 0 | F56: {=+_xll.EQNXTDZ($A$1,$B56,F$1,$B$1)} -> 0 | G56: {=+_xll.EQNXTDZ($A$1,$B56,G$1,$B$1)} -> 0 | H56: {=+_xll.EQNXTDZ($A$1,$B56,H$1,$B$1)} -> 0 | I56: {=+_xll.EQNXTDZ($A$1,$B56,I$1,$B$1)} -> 0 | J56: {=+_xll.EQNXTDZ($A$1,$B56,J$1,$B$1)} -> 0 | ... BK56: {=+_xll.EQNXTDZ($A$1,$B56,BK$1,$B$1)} -> 0
A57: Reserves & Surplus | B57: QTRB_RESERVE | C57: {=+_xll.EQNXTDZ($A$1,$B57,C$1,$B$1)} -> 0 | D57: {=+_xll.EQNXTDZ($A$1,$B57,D$1,$B$1)} -> 0 | E57: {=+_xll.EQNXTDZ($A$1,$B57,E$1,$B$1)} -> 0 | F57: {=+_xll.EQNXTDZ($A$1,$B57,F$1,$B$1)} -> 0 | G57: {=+_xll.EQNXTDZ($A$1,$B57,G$1,$B$1)} -> 0 | H57: {=+_xll.EQNXTDZ($A$1,$B57,H$1,$B$1)} -> 0 | I57: {=+_xll.EQNXTDZ($A$1,$B57,I$1,$B$1)} -> 0 | J57: {=+_xll.EQNXTDZ($A$1,$B57,J$1,$B$1)} -> 0 | ... BK57: {=+_xll.EQNXTDZ($A$1,$B57,BK$1,$B$1)} -> 0
